Workbook

Sheet Categorias
A1: CATEGORIA | B1: FLUXO DE CAIXA
A2: Recebimento de venda | B2: RECEITA
A3: Aluguel | B3: DESPESAS FIXAS
A4: Vale transporte | B4: DESPESAS FIXAS
A5: Fornecedor | B5: GASTOS VARIÁVEIS
A6: Salário | B6: DESPESAS FIXAS
A7: Material escritório/limpeza | B7: DESPESAS FIXAS
A8: Gás | B8: GASTOS VARIÁVEIS
A9: Combustível | B9: DESPESAS FIXAS
A10: Manutenção | B10: INVESTIMENTOS
A11: Impressão | B11: DESPESAS FIXAS
A12: Não Operacional | B12: NÃO OPERACIONAL
... A38: INSS | B38: DESPESAS FIXAS

Sheet FLUXO DE CAIXA  SIMPLIFICADO
B11: CANTINA BOM PRATO | E11: FEVEREIRO | G11: AV | K11: CMV
B12: Receita de Vendas | E12: {=_xlfn.IFS( $E$11="CONSOLIDADO", SUMIF(JANEIRO!$E$13:$E$412,"RECEITA",JANEIRO!$F$13:$F$412)+ SUMIF(FEVEREIRO!$E$13:$E$412,"RECEITA",FEVEREIRO!$F$13:$F$412)+ SUMIF(MARÇO!$E$13:$E$412,"RECEITA",MARÇO!$F$13:$F$412)+ SUMIF(ABRIL!$E$13:$E$415,"RECEITA",ABRIL!$F$13:$F$415)+ SUMIF(MAIO!$E$13:$E$418,"RECEITA",MAIO!$F$13:$F$418)+ SUMIF(JUNHO!$E$13:$E$419,"RECEITA",JUNHO!$F$13:$F$419)+ SUMIF(JULHO!$E$13:$E$412,"RECEITA",JULHO!$F$13:$F$412)+ SUMIF(AGOSTO!$E$13:$E$412,"RECEITA",AGOSTO!$F$13:$F$412)+ SUMIF(SETEMBRO!$E$13:$E$412,"RECEITA",SETEMBRO!$F$13:$F$412)+ SUMIF(OUTUBRO!$E$13:$E$412,"RECEITA",OUTUBRO!$F$13:$F$412)+ SUMIF(NOVEMBRO!$E$13:$E$412,"RECEITA",NOVEMBRO!$F$13:$F$412)+ SUMIF(DEZEMBRO!$E$13:$E$412,"RECEITA",DEZEMBRO!$F$13:$F$412), $E$11="JANEIRO",SUMIF(JANEIRO!$E$13:$E$412,"RECEITA",JANEIRO!$F$13:$F$412), $E$11="FEVEREIRO",SUMIF(FEVEREIRO!$E$13:$E$412,"RECEITA",FEVEREIRO!$F$13:$F$412), $E$11="MARÇO",SUMIF(MARÇO!$E$13:$E$412,"RECEITA",MARÇO!$F$13:$F$412), $E$11="ABRIL",SUMIF(ABRIL!$E$13:$E$415,"RECEITA",ABRIL!$F$13:$F$415), $E$11="MAIO",SUMIF(MAIO!$E$13:$E$418,"RECEITA",MAIO!$F$13:$F$418), $E$11="JUNHO",SUMIF(JUNHO!$E$13:$E$419,"RECEITA",JUNHO!$F$13:$F$419), $E$11="JULHO",SUMIF(JULHO!$E$13:$E$412,"RECEITA",JULHO!$F$13:$F$412), $E$11="AGOSTO",SUMIF(AGOSTO!$E$13:$E$412,"RECEITA",AGOSTO!$F$13:$F$412), $E$11="SETEMBRO",SUMIF(SETEMBRO!$E$13:$E$412,"RECEITA",SETEMBRO!$F$13:$F$412), $E$11="OUTUBRO",SUMIF(OUTUBRO!$E$13:$E$412,"RECEITA",OUTUBRO!$F$13:$F$412), $E$11="NOVEMBRO",SUMIF(NOVEMBRO!$E$13:$E$412,"RECEITA",NOVEMBRO!$F$13:$F$412), $E$11="DEZEMBRO",SUMIF(DEZEMBRO!$E$13:$E$412,"RECEITA",DEZEMBRO!$F$13:$F$412) )} -> 0 | G12: =E12/$E$12 -> #DIV/0! | K12: {=_xlfn.IFS( $E$11="CONSOLIDADO", SUMIF(JANEIRO!$D$13:$D$412,"FORNECEDOR",JANEIRO!$G$13:$G$412)+ SUMIF(FEVEREIRO!$D$13:$D$412,"FORNECEDOR",FEVEREIRO!$G$13:$G$412)+ SUMIF(MARÇO!$D$13:$D$412,"FORNECEDOR",MARÇO!$G$13:$G$412)+ SUMIF(ABRIL!$D$13:$D$415,"FORNECEDOR",ABRIL!$G$13:$G$415)+ SUMIF(MAIO!$D$13:$D$418,"FORNECEDOR",MAIO!$G$13:$G$418)+ SUMIF(JUNHO!$D$13:$D$419,"FORNECEDOR",JUNHO!$G$13:$G$419)+ SUMIF(JULHO!$D$13:$D$412,"FORNECEDOR",JULHO!$G$13:$G$412)+ SUMIF(AGOSTO!$D$13:$D$412,"FORNECEDOR",AGOSTO!$G$13:$G$412)+ SUMIF(SETEMBRO!$D$13:$D$412,"FORNECEDOR",SETEMBRO!$G$13:$G$412)+ SUMIF(OUTUBRO!$D$13:$D$412,"FORNECEDOR",OUTUBRO!$G$13:$G$412)+ SUMIF(NOVEMBRO!$D$13:$D$412,"FORNECEDOR",NOVEMBRO!$G$13:$G$412)+ SUMIF(DEZEMBRO!$D$13:$D$412,"FORNECEDOR",DEZEMBRO!$G$13:$G$412), $E$11="JANEIRO",SUMIF(JANEIRO!$D$13:$D$412,"FORNECEDOR",JANEIRO!$G$13:$G$412), $E$11="FEVEREIRO",SUMIF(FEVEREIRO!$D$13:$D$412,"FORNECEDOR",FEVEREIRO!$G$13:$G$412), $E$11="MARÇO",SUMIF(MARÇO!$D$13:$D$412,"FORNECEDOR",MARÇO!$G$13:$G$412), $E$11="ABRIL",SUMIF(ABRIL!$D$13:$D$415,"FORNECEDOR",ABRIL!$G$13:$G$415), $E$11="MAIO",SUMIF(MAIO!$D$13:$D$418,"FORNECEDOR",MAIO!$G$13:$G$418), $E$11="JUNHO",SUMIF(JUNHO!$D$13:$D$419,"FORNECEDOR",JUNHO!$G$13:$G$419), $E$11="JULHO",SUMIF(JULHO!$D$13:$D$412,"FORNECEDOR",JULHO!$G$13:$G$412), $E$11="AGOSTO",SUMIF(AGOSTO!$D$13:$D$412,"FORNECEDOR",AGOSTO!$G$13:$G$412), $E$11="SETEMBRO",SUMIF(SETEMBRO!$D$13:$D$412,"FORNECEDOR",SETEMBRO!$G$13:$G$412), $E$11="OUTUBRO",SUMIF(OUTUBRO!$D$13:$D$412,"FORNECEDOR",OUTUBRO!$G$13:$G$412), $E$11="NOVEMBRO",SUMIF(NOVEMBRO!$D$13:$D$412,"FORNECEDOR",NOVEMBRO!$G$13:$G$412), $E$11="DEZEMBRO",SUMIF(DEZEMBRO!$D$13:$D$412,"FORNECEDOR",DEZEMBRO!$G$13:$G$412) )} -> 0 | M12: =(K12/E12)*-1 -> #DIV/0!
B13: Gastos Variáveis | E13: {=_xlfn.IFS( $E$11="CONSOLIDADO", SUMIF(JANEIRO!$E$13:$E$412,"GASTOS VARIÁVEIS",JANEIRO!$G$13:$G$412)+ SUMIF(FEVEREIRO!$E$13:$E$412,"GASTOS VARIÁVEIS",FEVEREIRO!$G$13:$G$412)+ SUMIF(MARÇO!$E$13:$E$412,"GASTOS VARIÁVEIS",MARÇO!$G$13:$G$412)+ SUMIF(ABRIL!$E$13:$E$415,"GASTOS VARIÁVEIS",ABRIL!$G$13:$G$415)+ SUMIF(MAIO!$E$13:$E$418,"GASTOS VARIÁVEIS",MAIO!$G$13:$G$418)+ SUMIF(JUNHO!$E$13:$E$419,"GASTOS VARIÁVEIS",JUNHO!$G$13:$G$419)+ SUMIF(JULHO!$E$13:$E$412,"GASTOS VARIÁVEIS",JULHO!$G$13:$G$412)+ SUMIF(AGOSTO!$E$13:$E$412,"GASTOS VARIÁVEIS",AGOSTO!$G$13:$G$412)+ SUMIF(SETEMBRO!$E$13:$E$412,"GASTOS VARIÁVEIS",SETEMBRO!$G$13:$G$412)+ SUMIF(OUTUBRO!$E$13:$E$412,"GASTOS VARIÁVEIS",OUTUBRO!$G$13:$G$412)+ SUMIF(NOVEMBRO!$E$13:$E$412,"GASTOS VARIÁVEIS",NOVEMBRO!$G$13:$G$412)+ SUMIF(DEZEMBRO!$E$13:$E$412,"GASTOS VARIÁVEIS",DEZEMBRO!$G$13:$G$412), $E$11="JANEIRO",SUMIF(JANEIRO!$E$13:$E$412,"GASTOS VARIÁVEIS",JANEIRO!$G$13:$G$412), $E$11="FEVEREIRO",SUMIF(FEVEREIRO!$E$13:$E$412,"GASTOS VARIÁVEIS",FEVEREIRO!$G$13:$G$412), $E$11="MARÇO",SUMIF(MARÇO!$E$13:$E$412,"GASTOS VARIÁVEIS",MARÇO!$G$13:$G$412), $E$11="ABRIL",SUMIF(ABRIL!$E$13:$E$415,"GASTOS VARIÁVEIS",ABRIL!$G$13:$G$415), $E$11="MAIO",SUMIF(MAIO!$E$13:$E$418,"GASTOS VARIÁVEIS",MAIO!$G$13:$G$418), $E$11="JUNHO",SUMIF(JUNHO!$E$13:$E$419,"GASTOS VARIÁVEIS",JUNHO!$G$13:$G$419), $E$11="JULHO",SUMIF(JULHO!$E$13:$E$412,"GASTOS VARIÁVEIS",JULHO!$G$13:$G$412), $E$11="AGOSTO",SUMIF(AGOSTO!$E$13:$E$412,"GASTOS VARIÁVEIS",AGOSTO!$G$13:$G$412), $E$11="SETEMBRO",SUMIF(SETEMBRO!$E$13:$E$412,"GASTOS VARIÁVEIS",SETEMBRO!$G$13:$G$412), $E$11="OUTUBRO",SUMIF(OUTUBRO!$E$13:$E$412,"GASTOS VARIÁVEIS",OUTUBRO!$G$13:$G$412), $E$11="NOVEMBRO",SUMIF(NOVEMBRO!$E$13:$E$412,"GASTOS VARIÁVEIS",NOVEMBRO!$G$13:$G$412), $E$11="DEZEMBRO",SUMIF(DEZEMBRO!$E$13:$E$412,"GASTOS VARIÁVEIS",DEZEMBRO!$G$13:$G$412) )} -> 0 | G13: =E13/$E$12 -> #DIV/0!
B14: Margem de Contribuição | E14: =E12-E13 -> 0 | G14: =E14/$E$12 -> #DIV/0!
B15: Despesas Fixas | E15: {=_xlfn.IFS( $E$11="CONSOLIDADO", SUMIF(JANEIRO!$E$13:$E$412,"DESPESAS FIXAS",JANEIRO!$G$13:$G$412)+ SUMIF(FEVEREIRO!$E$13:$E$412,"DESPESAS FIXAS",FEVEREIRO!$G$13:$G$412)+ SUMIF(MARÇO!$E$13:$E$412,"DESPESAS FIXAS",MARÇO!$G$13:$G$412)+ SUMIF(ABRIL!$E$13:$E$415,"DESPESAS FIXAS",ABRIL!$G$13:$G$415)+ SUMIF(MAIO!$E$13:$E$418,"DESPESAS FIXAS",MAIO!$G$13:$G$418)+ SUMIF(JUNHO!$E$13:$E$419,"DESPESAS FIXAS",JUNHO!$G$13:$G$419)+ SUMIF(JULHO!$E$13:$E$412,"DESPESAS FIXAS",JULHO!$G$13:$G$412)+ SUMIF(AGOSTO!$E$13:$E$412,"DESPESAS FIXAS",AGOSTO!$G$13:$G$412)+ SUMIF(SETEMBRO!$E$13:$E$412,"DESPESAS FIXAS",SETEMBRO!$G$13:$G$412)+ SUMIF(OUTUBRO!$E$13:$E$412,"DESPESAS FIXAS",OUTUBRO!$G$13:$G$412)+ SUMIF(NOVEMBRO!$E$13:$E$412,"DESPESAS FIXAS",NOVEMBRO!$G$13:$G$412)+ SUMIF(DEZEMBRO!$E$13:$E$412,"DESPESAS FIXAS",DEZEMBRO!$G$13:$G$412), $E$11="JANEIRO",SUMIF(JANEIRO!$E$13:$E$412,"DESPESAS FIXAS",JANEIRO!$G$13:$G$412), $E$11="FEVEREIRO",SUMIF(FEVEREIRO!$E$13:$E$412,"DESPESAS FIXAS",FEVEREIRO!$G$13:$G$412), $E$11="MARÇO",SUMIF(MARÇO!$E$13:$E$412,"DESPESAS FIXAS",MARÇO!$G$13:$G$412), $E$11="ABRIL",SUMIF(ABRIL!$E$13:$E$415,"DESPESAS FIXAS",ABRIL!$G$13:$G$415), $E$11="MAIO",SUMIF(MAIO!$E$13:$E$418,"DESPESAS FIXAS",MAIO!$G$13:$G$418), $E$11="JUNHO",SUMIF(JUNHO!$E$13:$E$419,"DESPESAS FIXAS",JUNHO!$G$13:$G$419), $E$11="JULHO",SUMIF(JULHO!$E$13:$E$412,"DESPESAS FIXAS",JULHO!$G$13:$G$412), $E$11="AGOSTO",SUMIF(AGOSTO!$E$13:$E$412,"DESPESAS FIXAS",AGOSTO!$G$13:$G$412), $E$11="SETEMBRO",SUMIF(SETEMBRO!$E$13:$E$412,"DESPESAS FIXAS",SETEMBRO!$G$13:$G$412), $E$11="OUTUBRO",SUMIF(OUTUBRO!$E$13:$E$412,"DESPESAS FIXAS",OUTUBRO!$G$13:$G$412), $E$11="NOVEMBRO",SUMIF(NOVEMBRO!$E$13:$E$412,"DESPESAS FIXAS",NOVEMBRO!$G$13:$G$412), $E$11="DEZEMBRO",SUMIF(DEZEMBRO!$E$13:$E$412,"DESPESAS FIXAS",DEZEMBRO!$G$13:$G$412) )} -> 0 | G15: =E15/$E$12 -> #DIV/0! | K15: PONTO DE EQUILIBRIO
B16: Lucro antes Investimentos | E16: =E14-E15 -> 0 | G16: =E16/$E$12 -> #DIV/0! | K16: =(E15+E17+E19)/G14*-1 -> #DIV/0!
B17: Investimentos | E17: {=_xlfn.IFS( $E$11="CONSOLIDADO", SUMIF(JANEIRO!$E$13:$E$412,"INVESTIMENTOS",JANEIRO!$G$13:$G$412)+ SUMIF(FEVEREIRO!$E$13:$E$412,"INVESTIMENTOS",FEVEREIRO!$G$13:$G$412)+ SUMIF(MARÇO!$E$13:$E$412,"INVESTIMENTOS",MARÇO!$G$13:$G$412)+ SUMIF(ABRIL!$E$13:$E$415,"INVESTIMENTOS",ABRIL!$G$13:$G$415)+ SUMIF(MAIO!$E$13:$E$418,"INVESTIMENTOS",MAIO!$G$13:$G$418)+ SUMIF(JUNHO!$E$13:$E$419,"INVESTIMENTOS",JUNHO!$G$13:$G$419)+ SUMIF(JULHO!$E$13:$E$412,"INVESTIMENTOS",JULHO!$G$13:$G$412)+ SUMIF(AGOSTO!$E$13:$E$412,"INVESTIMENTOS",AGOSTO!$G$13:$G$412)+ SUMIF(SETEMBRO!$E$13:$E$412,"INVESTIMENTOS",SETEMBRO!$G$13:$G$412)+ SUMIF(OUTUBRO!$E$13:$E$412,"INVESTIMENTOS",OUTUBRO!$G$13:$G$412)+ SUMIF(NOVEMBRO!$E$13:$E$412,"INVESTIMENTOS",NOVEMBRO!$G$13:$G$412)+ SUMIF(DEZEMBRO!$E$13:$E$412,"INVESTIMENTOS",DEZEMBRO!$G$13:$G$412), $E$11="JANEIRO",SUMIF(JANEIRO!$E$13:$E$412,"INVESTIMENTOS",JANEIRO!$G$13:$G$412), $E$11="FEVEREIRO",SUMIF(FEVEREIRO!$E$13:$E$412,"INVESTIMENTOS",FEVEREIRO!$G$13:$G$412), $E$11="MARÇO",SUMIF(MARÇO!$E$13:$E$412,"INVESTIMENTOS",MARÇO!$G$13:$G$412), $E$11="ABRIL",SUMIF(ABRIL!$E$13:$E$415,"INVESTIMENTOS",ABRIL!$G$13:$G$415), $E$11="MAIO",SUMIF(MAIO!$E$13:$E$418,"INVESTIMENTOS",MAIO!$G$13:$G$418), $E$11="JUNHO",SUMIF(JUNHO!$E$13:$E$419,"INVESTIMENTOS",JUNHO!$G$13:$G$419), $E$11="JULHO",SUMIF(JULHO!$E$13:$E$412,"INVESTIMENTOS",JULHO!$G$13:$G$412), $E$11="AGOSTO",SUMIF(AGOSTO!$E$13:$E$412,"INVESTIMENTOS",AGOSTO!$G$13:$G$412), $E$11="SETEMBRO",SUMIF(SETEMBRO!$E$13:$E$412,"INVESTIMENTOS",SETEMBRO!$G$13:$G$412), $E$11="OUTUBRO",SUMIF(OUTUBRO!$E$13:$E$412,"INVESTIMENTOS",OUTUBRO!$G$13:$G$412), $E$11="NOVEMBRO",SUMIF(NOVEMBRO!$E$13:$E$412,"INVESTIMENTOS",NOVEMBRO!$G$13:$G$412), $E$11="DEZEMBRO",SUMIF(DEZEMBRO!$E$13:$E$412,"INVESTIMENTOS",DEZEMBRO!$G$13:$G$412) )} -> 0 | G17: =E17/$E$12 -> #DIV/0!
B18: Lucro Operacional | E18: =E16-E17 -> 0 | G18: =E18/$E$12 -> #DIV/0!
B19: Não Operacional | E19: {=_xlfn.IFS( $E$11="CONSOLIDADO", SUMIF(JANEIRO!$E$13:$E$412,"NÃO OPERACIONAL",JANEIRO!$G$13:$G$412)+ SUMIF(FEVEREIRO!$E$13:$E$412,"NÃO OPERACIONAL",FEVEREIRO!$G$13:$G$412)+ SUMIF(MARÇO!$E$13:$E$412,"NÃO OPERACIONAL",MARÇO!$G$13:$G$412)+ SUMIF(ABRIL!$E$13:$E$415,"NÃO OPERACIONAL",ABRIL!$G$13:$G$415)+ SUMIF(MAIO!$E$13:$E$418,"NÃO OPERACIONAL",MAIO!$G$13:$G$418)+ SUMIF(JUNHO!$E$13:$E$419,"NÃO OPERACIONAL",JUNHO!$G$13:$G$419)+ SUMIF(JULHO!$E$13:$E$412,"NÃO OPERACIONAL",JULHO!$G$13:$G$412)+ SUMIF(AGOSTO!$E$13:$E$412,"NÃO OPERACIONAL",AGOSTO!$G$13:$G$412)+ SUMIF(SETEMBRO!$E$13:$E$412,"NÃO OPERACIONAL",SETEMBRO!$G$13:$G$412)+ SUMIF(OUTUBRO!$E$13:$E$412,"NÃO OPERACIONAL",OUTUBRO!$G$13:$G$412)+ SUMIF(NOVEMBRO!$E$13:$E$412,"NÃO OPERACIONAL",NOVEMBRO!$G$13:$G$412)+ SUMIF(DEZEMBRO!$E$13:$E$412,"NÃO OPERACIONAL",DEZEMBRO!$G$13:$G$412), $E$11="JANEIRO",SUMIF(JANEIRO!$E$13:$E$412,"NÃO OPERACIONAL",JANEIRO!$G$13:$G$412), $E$11="FEVEREIRO",SUMIF(FEVEREIRO!$E$13:$E$412,"NÃO OPERACIONAL",FEVEREIRO!$G$13:$G$412), $E$11="MARÇO",SUMIF(MARÇO!$E$13:$E$412,"NÃO OPERACIONAL",MARÇO!$G$13:$G$412), $E$11="ABRIL",SUMIF(ABRIL!$E$13:$E$415,"NÃO OPERACIONAL",ABRIL!$G$13:$G$415), $E$11="MAIO",SUMIF(MAIO!$E$13:$E$418,"NÃO OPERACIONAL",MAIO!$G$13:$G$418), $E$11="JUNHO",SUMIF(JUNHO!$E$13:$E$419,"NÃO OPERACIONAL",JUNHO!$G$13:$G$419), $E$11="JULHO",SUMIF(JULHO!$E$13:$E$412,"NÃO OPERACIONAL",JULHO!$G$13:$G$412), $E$11="AGOSTO",SUMIF(AGOSTO!$E$13:$E$412,"NÃO OPERACIONAL",AGOSTO!$G$13:$G$412), $E$11="SETEMBRO",SUMIF(SETEMBRO!$E$13:$E$412,"NÃO OPERACIONAL",SETEMBRO!$G$13:$G$412), $E$11="OUTUBRO",SUMIF(OUTUBRO!$E$13:$E$412,"NÃO OPERACIONAL",OUTUBRO!$G$13:$G$412), $E$11="NOVEMBRO",SUMIF(NOVEMBRO!$E$13:$E$412,"NÃO OPERACIONAL",NOVEMBRO!$G$13:$G$412), $E$11="DEZEMBRO",SUMIF(DEZEMBRO!$E$13:$E$412,"NÃO OPERACIONAL",DEZEMBRO!$G$13:$G$412) )} -> 0 | G19: =E19/$E$12 -> #DIV/0!
B20: Resultado do período | E20: =E18-E19 -> 0 | G20: =E20/$E$12 -> #DIV/0!
B1048557: JANEIRO
B1048558: FEVEREIRO
B1048559: MARÇO
B1048560: ABRIL
B1048561: MAIO
B1048562: JUNHO
B1048563: JULHO
B1048564: AGOSTO
B1048565: SETEMBRO
B1048566: OUTUBRO
B1048567: NOVEMBRO
B1048568: DEZEMBRO
B1048569: CONSOLIDADO

Sheet ANÁLISE
A1: MESES | B1: RECEITA | C1: DESPESAS
A2: JAN | B2: =SUMIF(JANEIRO!E13:E254,"RECEITA",JANEIRO!F13:F254) -> 0 | C2: =(SUMIF(JANEIRO!$E$13:$E$412,"GASTOS VARIÁVEIS",JANEIRO!$G$13:$G$412)+ SUMIF(JANEIRO!$E$13:$E$412,"DESPESAS FIXAS",JANEIRO!$G$13:$G$412)+ SUMIF(JANEIRO!$E$13:$E$412,"INVESTIMENTOS",JANEIRO!$G$13:$G$412)+ SUMIF(JANEIRO!$E$13:$E$412,"NÃO OPERACIONAL",JANEIRO!$G$13:$G$412)) -> 0 | E2: Mês | F2: Fórmula
A3: FEV | B3: =SUMIF(FEVEREIRO!E14:E255,"RECEITA",FEVEREIRO!F14:F255) -> 0 | C3: =(SUMIF(FEVEREIRO!$E$13:$E$412,"GASTOS VARIÁVEIS",FEVEREIRO!$G$13:$G$412)+ SUMIF(FEVEREIRO!$E$13:$E$412,"DESPESAS FIXAS",FEVEREIRO!$G$13:$G$412)+ SUMIF(FEVEREIRO!$E$13:$E$412,"INVESTIMENTOS",FEVEREIRO!$G$13:$G$412)+ SUMIF(FEVEREIRO!$E$13:$E$412,"NÃO OPERACIONAL",FEVEREIRO!$G$13:$G$412))*-1 -> 0 | E3: MARÇO
A4: MAR | B4: =SUMIF(MARÇO!E14:E255,"RECEITA",MARÇO!F14:F255) -> 0 | C4: =(SUMIF(MARÇO!$E$13:$E$412,"GASTOS VARIÁVEIS",MARÇO!$G$13:$G$412)+SUMIF(MARÇO!$E$13:$E$412,"DESPESAS FIXAS",MARÇO!$G$13:$G$412)+SUMIF(MARÇO!$E$13:$E$412,"INVESTIMENTOS",MARÇO!$G$13:$G$412)+SUMIF(MARÇO!$E$13:$E$412,"NÃO OPERACIONAL",MARÇO!$G$13:$G$412))*-1 -> 0 | E4: ABRIL
A5: ABR | B5: =SUMIF(ABRIL!E14:E258,"RECEITA",ABRIL!F14:F258) -> 0 | C5: =(SUMIF(ABRIL!$E$13:$E$415,"GASTOS VARIÁVEIS",ABRIL!$G$13:$G$415)+SUMIF(ABRIL!$E$13:$E$415,"DESPESAS FIXAS",ABRIL!$G$13:$G$415)+SUMIF(ABRIL!$E$13:$E$415,"INVESTIMENTOS",ABRIL!$G$13:$G$415)+SUMIF(ABRIL!$E$13:$E$415,"NÃO OPERACIONAL",ABRIL!$G$13:$G$415))*-1 -> 0 | E5: MAIO
A6: MAI | B6: =SUMIF(MAIO!E14:E261,"RECEITA",MAIO!F14:F261) -> 7852.18 | C6: =(SUMIF(MAIO!$E$13:$E$418,"GASTOS VARIÁVEIS",MAIO!$G$13:$G$418)+SUMIF(MAIO!$E$13:$E$418,"DESPESAS FIXAS",MAIO!$G$13:$G$418)+SUMIF(MAIO!$E$13:$E$418,"INVESTIMENTOS",MAIO!$G$13:$G$418)+SUMIF(MAIO!$E$13:$E$418,"NÃO OPERACIONAL",MAIO!$G$13:$G$418))*-1 -> -7128.06 | E6: JUNHO
A7: JUN | B7: =SUMIF(JUNHO!E15:E262,"RECEITA",JUNHO!F15:F262) -> 2335.81 | C7: =(SUMIF(JUNHO!$E$13:$E$419,"GASTOS VARIÁVEIS",JUNHO!$G$13:$G$419)+SUMIF(JUNHO!$E$13:$E$419,"DESPESAS FIXAS",JUNHO!$G$13:$G$419)+SUMIF(JUNHO!$E$13:$E$419,"INVESTIMENTOS",JUNHO!$G$13:$G$419)+SUMIF(JUNHO!$E$13:$E$419,"NÃO OPERACIONAL",JUNHO!$G$13:$G$419))*-1 -> -2529.6 | E7: JULHO
A8: JUL | B8: =SUMIF(JULHO!E14:E255,"RECEITA",JULHO!F14:F255) -> 0 | C8: =(SUMIF(JULHO!$E$13:$E$412,"GASTOS VARIÁVEIS",JULHO!$G$13:$G$412)+SUMIF(JULHO!$E$13:$E$412,"DESPESAS FIXAS",JULHO!$G$13:$G$412)+SUMIF(JULHO!$E$13:$E$412,"INVESTIMENTOS",JULHO!$G$13:$G$412)+SUMIF(JULHO!$E$13:$E$412,"NÃO OPERACIONAL",JULHO!$G$13:$G$412))*-1 -> 0 | E8: AGOSTO
A9: AGO | B9: =SUMIF(AGOSTO!E14:E255,"RECEITA",AGOSTO!F14:F255) -> 0 | C9: =(SUMIF(AGOSTO!$E$13:$E$412,"GASTOS VARIÁVEIS",AGOSTO!$G$13:$G$412)+SUMIF(AGOSTO!$E$13:$E$412,"DESPESAS FIXAS",AGOSTO!$G$13:$G$412)+SUMIF(AGOSTO!$E$13:$E$412,"INVESTIMENTOS",AGOSTO!$G$13:$G$412)+SUMIF(AGOSTO!$E$13:$E$412,"NÃO OPERACIONAL",AGOSTO!$G$13:$G$412))*-1 -> 0 | E9: SETEMBRO
A10: SET | B10: =SUMIF(SETEMBRO!E14:E255,"RECEITA",SETEMBRO!F14:F255) -> 0 | C10: =(SUMIF(SETEMBRO!$E$13:$E$412,"GASTOS VARIÁVEIS",SETEMBRO!$G$13:$G$412)+SUMIF(SETEMBRO!$E$13:$E$412,"DESPESAS FIXAS",SETEMBRO!$G$13:$G$412)+SUMIF(SETEMBRO!$E$13:$E$412,"INVESTIMENTOS",SETEMBRO!$G$13:$G$412)+SUMIF(SETEMBRO!$E$13:$E$412,"NÃO OPERACIONAL",SETEMBRO!$G$13:$G$412))*-1 -> 0 | E10: OUTUBRO
A11: OUT | B11: =SUMIF(OUTUBRO!E14:E255,"RECEITA",OUTUBRO!F14:F255) -> 0 | C11: =(SUMIF(OUTUBRO!$E$13:$E$412,"GASTOS VARIÁVEIS",OUTUBRO!$G$13:$G$412)+SUMIF(OUTUBRO!$E$13:$E$412,"DESPESAS FIXAS",OUTUBRO!$G$13:$G$412)+SUMIF(OUTUBRO!$E$13:$E$412,"INVESTIMENTOS",OUTUBRO!$G$13:$G$412)+SUMIF(OUTUBRO!$E$13:$E$412,"NÃO OPERACIONAL",OUTUBRO!$G$13:$G$412))*-1 -> 0 | E11: NOVEMBRO
A12: NOV | B12: =SUMIF(NOVEMBRO!E14:E255,"RECEITA",NOVEMBRO!F14:F255) -> 0 | C12: =(SUMIF(NOVEMBRO!$E$13:$E$412,"GASTOS VARIÁVEIS",NOVEMBRO!$G$13:$G$412)+SUMIF(NOVEMBRO!$E$13:$E$412,"DESPESAS FIXAS",NOVEMBRO!$G$13:$G$412)+SUMIF(NOVEMBRO!$E$13:$E$412,"INVESTIMENTOS",NOVEMBRO!$G$13:$G$412)+SUMIF(NOVEMBRO!$E$13:$E$412,"NÃO OPERACIONAL",NOVEMBRO!$G$13:$G$412))*-1 -> 0 | E12: DEZEMBRO
A13: DEZ | B13: =SUMIF(DEZEMBRO!E14:E255,"RECEITA",DEZEMBRO!F14:F255) -> 0 | C13: =(SUMIF(DEZEMBRO!$E$13:$E$412,"GASTOS VARIÁVEIS",DEZEMBRO!$G$13:$G$412)+SUMIF(DEZEMBRO!$E$13:$E$412,"DESPESAS FIXAS",DEZEMBRO!$G$13:$G$412)+SUMIF(DEZEMBRO!$E$13:$E$412,"INVESTIMENTOS",DEZEMBRO!$G$13:$G$412)+SUMIF(DEZEMBRO!$E$13:$E$412,"NÃO OPERACIONAL",DEZEMBRO!$G$13:$G$412))*-1 -> 0
A16: MESES | B16: DESPESAS
A17: JAN | B17: =C2 -> 0
A18: FEV | B18: =C3 -> 0
A19: MAR | B19: =C4 -> 0
A20: ABR | B20: =C5 -> 0
A21: MAI | B21: =C6 -> -7128.06
A22: JUN | B22: =C7 -> -2529.6
A23: JUL | B23: =C8 -> 0
A24: AGO | B24: =C9 -> 0
A25: SET | B25: =C10 -> 0
A26: OUT | B26: =C11 -> 0
A27: NOV | B27: =C12 -> 0
A28: DEZ | B28: =C13 -> 0
A1048545: JANEIRO
A1048546: FEVEREIRO
A1048547: MARÇO
A1048548: ABRIL
A1048549: MAIO
A1048550: JUNHO
A1048551: JULHO
A1048552: AGOSTO
A1048553: SETEMBRO
A1048554: OUTUBRO
A1048555: NOVEMBRO
A1048556: DEZEMBRO

Sheet JANEIRO
B2: CONTROLE DE CAIXA
B7: SALDO INICIAL: | G7: =D8+D9+D10+G8+G9+G10 -> 0
B8: BANCO DO BRASIL: | E8: BANCO 4:
B9: BANCO 2: | E9: BANCO 5:
B10: BANCO 3: | E10: DINHEIRO EM ESPÉCIE:
B12: Data | C12: Descrição | D12: Categoria | E12: Fluxo de Caixa | F12: Entrada | G12: Saída | H12: Saldo
E13: =IF(ISERROR(VLOOKUP(D13,Categorias!A:B,2,0)),"",VLOOKUP(D13,Categorias!A:B,2,0))
E14: =IF(ISERROR(VLOOKUP(D14,Categorias!A:B,2,0)),"",VLOOKUP(D14,Categorias!A:B,2,0))
E15: =IF(ISERROR(VLOOKUP(D15,Categorias!A:B,2,0)),"",VLOOKUP(D15,Categorias!A:B,2,0))
E16: =IF(ISERROR(VLOOKUP(D16,Categorias!A:B,2,0)),"",VLOOKUP(D16,Categorias!A:B,2,0))
E17: =IF(ISERROR(VLOOKUP(D17,Categorias!A:B,2,0)),"",VLOOKUP(D17,Categorias!A:B,2,0))
E18: =IF(ISERROR(VLOOKUP(D18,Categorias!A:B,2,0)),"",VLOOKUP(D18,Categorias!A:B,2,0))
E19: =IF(ISERROR(VLOOKUP(D19,Categorias!A:B,2,0)),"",VLOOKUP(D19,Categorias!A:B,2,0))
E20: =IF(ISERROR(VLOOKUP(D20,Categorias!A:B,2,0)),"",VLOOKUP(D20,Categorias!A:B,2,0))
E21: =IF(ISERROR(VLOOKUP(D21,Categorias!A:B,2,0)),"",VLOOKUP(D21,Categorias!A:B,2,0)) | N21: mei
E22: =IF(ISERROR(VLOOKUP(D22,Categorias!A:B,2,0)),"",VLOOKUP(D22,Categorias!A:B,2,0))
E23: =IF(ISERROR(VLOOKUP(D23,Categorias!A:B,2,0)),"",VLOOKUP(D23,Categorias!A:B,2,0))
E24: =IF(ISERROR(VLOOKUP(D24,Categorias!A:B,2,0)),"",VLOOKUP(D24,Categorias!A:B,2,0))
E25: =IF(ISERROR(VLOOKUP(D25,Categorias!A:B,2,0)),"",VLOOKUP(D25,Categorias!A:B,2,0))
E26: =IF(ISERROR(VLOOKUP(D26,Categorias!A:B,2,0)),"",VLOOKUP(D26,Categorias!A:B,2,0))
E27: =IF(ISERROR(VLOOKUP(D27,Categorias!A:B,2,0)),"",VLOOKUP(D27,Categorias!A:B,2,0))
E28: =IF(ISERROR(VLOOKUP(D28,Categorias!A:B,2,0)),"",VLOOKUP(D28,Categorias!A:B,2,0))
E29: =IF(ISERROR(VLOOKUP(D29,Categorias!A:B,2,0)),"",VLOOKUP(D29,Categorias!A:B,2,0))
E30: =IF(ISERROR(VLOOKUP(D30,Categorias!A:B,2,0)),"",VLOOKUP(D30,Categorias!A:B,2,0))
E31: =IF(ISERROR(VLOOKUP(D31,Categorias!A:B,2,0)),"",VLOOKUP(D31,Categorias!A:B,2,0))
E32: =IF(ISERROR(VLOOKUP(D32,Categorias!A:B,2,0)),"",VLOOKUP(D32,Categorias!A:B,2,0))
E33: =IF(ISERROR(VLOOKUP(D33,Categorias!A:B,2,0)),"",VLOOKUP(D33,Categorias!A:B,2,0))
... E278: =IF(ISERROR(VLOOKUP(D278,Categorias!A:B,2,0)),"",VLOOKUP(D278,Categorias!A:B,2,0))

Sheet FEVEREIRO
B2: CONTROLE DE CAIXA
B7: SALDOS INICIAL: | G7: =D8+D9+D10+G8+G9+G10 -> 3500
B8: MERCADO PAGO | D8: 2500 | E8: BANCO 4: | G8: 0
B9: NUBANK | D9: 1000 | E9: BANCO 5: | G9: 0
B10: BANCO 3: | D10: 0 | E10: DINHEIRO EM ESPÉCIE: | G10: 0
B12: Data | C12: Descrição | D12: Categoria | E12: Fluxo de Caixa | F12: Entrada | G12: Saída | H12: Saldo
B13: 46054 | C13: COMPRA DE CAFÉ | D13: Fornecedor | E13: =IF(ISERROR(VLOOKUP(D13,Categorias!A:B,2,0)),"",VLOOKUP(D13,Categorias!A:B,2,0)) -> GASTOS VARIÁVEIS
B14: 46055 | C14: COMPRA DE AÇUCAR | D14: Fornecedor | E14: =IF(ISERROR(VLOOKUP(D14,Categorias!A:B,2,0)),"",VLOOKUP(D14,Categorias!A:B,2,0)) -> GASTOS VARIÁVEIS
B15: 46056 | C15: COMPRA DE MASSA DE TAPIOCA | D15: Fornecedor | E15: =IF(ISERROR(VLOOKUP(D15,Categorias!A:B,2,0)),"",VLOOKUP(D15,Categorias!A:B,2,0)) -> GASTOS VARIÁVEIS
B16: 46057 | C16: PAGAMENTO DE ALUGUEL | D16: Aluguel | E16: =IF(ISERROR(VLOOKUP(D16,Categorias!A:B,2,0)),"",VLOOKUP(D16,Categorias!A:B,2,0)) -> DESPESAS FIXAS
B17: 46058 | C17: RECEBIMENTO DE VENDAS DO DIA | D17: Recebimento de venda | E17: =IF(ISERROR(VLOOKUP(D17,Categorias!A:B,2,0)),"",VLOOKUP(D17,Categorias!A:B,2,0)) -> RECEITA
B18: 46059 | C18: EQUATORIAL | D18: Energia Elétrica | E18: =IF(ISERROR(VLOOKUP(D18,Categorias!A:B,2,0)),"",VLOOKUP(D18,Categorias!A:B,2,0)) -> DESPESAS FIXAS
B19: 46060 | C19: PAGAMENTO DE SALÁRIOS | D19: Salário | E19: =IF(ISERROR(VLOOKUP(D19,Categorias!A:B,2,0)),"",VLOOKUP(D19,Categorias!A:B,2,0)) -> DESPESAS FIXAS
B20: 46061 | C20: FGTS | D20: FGTS | E20: =IF(ISERROR(VLOOKUP(D20,Categorias!A:B,2,0)),"",VLOOKUP(D20,Categorias!A:B,2,0)) -> DESPESAS FIXAS
B21: 46062 | C21: EMPRÉSTIMO BANCÁRIO | D21: Empréstimos | E21: =IF(ISERROR(VLOOKUP(D21,Categorias!A:B,2,0)),"",VLOOKUP(D21,Categorias!A:B,2,0)) -> NÃO OPERACIONAL
B22: 46063 | C22: APORTE DO SÓCIO | D22: Aporte de capital | E22: =IF(ISERROR(VLOOKUP(D22,Categorias!A:B,2,0)),"",VLOOKUP(D22,Categorias!A:B,2,0)) -> NÃO OPERACIONAL
B23: 46064 | C23: MARKETING | D23: Marketing | E23: =IF(ISERROR(VLOOKUP(D23,Categorias!A:B,2,0)),"",VLOOKUP(D23,Categorias!A:B,2,0)) -> INVESTIMENTOS
B24: 46065 | C24: RECEBIMENTO DE VENDAS DO DIA | D24: Recebimento de venda | E24: =IF(ISERROR(VLOOKUP(D24,Categorias!A:B,2,0)),"",VLOOKUP(D24,Categorias!A:B,2,0)) -> RECEITA
... B29: 46070 | C29: TARIFAS BANCÁRIAS | D29: Não Operacional | E29: =IF(ISERROR(VLOOKUP(D29,Categorias!A:B,2,0)),"",VLOOKUP(D29,Categorias!A:B,2,0)) -> NÃO OPERACIONAL
B30: 46071 | E30: =IF(ISERROR(VLOOKUP(D30,Categorias!A:B,2,0)),"",VLOOKUP(D30,Categorias!A:B,2,0))
B31: 46072 | E31: =IF(ISERROR(VLOOKUP(D31,Categorias!A:B,2,0)),"",VLOOKUP(D31,Categorias!A:B,2,0))
B32: 46073 | E32: =IF(ISERROR(VLOOKUP(D32,Categorias!A:B,2,0)),"",VLOOKUP(D32,Categorias!A:B,2,0))
B33: 46074 | E33: =IF(ISERROR(VLOOKUP(D33,Categorias!A:B,2,0)),"",VLOOKUP(D33,Categorias!A:B,2,0))
B34: 46075 | E34: =IF(ISERROR(VLOOKUP(D34,Categorias!A:B,2,0)),"",VLOOKUP(D34,Categorias!A:B,2,0))
B35: 46076 | E35: =IF(ISERROR(VLOOKUP(D35,Categorias!A:B,2,0)),"",VLOOKUP(D35,Categorias!A:B,2,0))
B36: 46077 | E36: =IF(ISERROR(VLOOKUP(D36,Categorias!A:B,2,0)),"",VLOOKUP(D36,Categorias!A:B,2,0))
B37: 46078 | E37: =IF(ISERROR(VLOOKUP(D37,Categorias!A:B,2,0)),"",VLOOKUP(D37,Categorias!A:B,2,0))
B38: 46079 | E38: =IF(ISERROR(VLOOKUP(D38,Categorias!A:B,2,0)),"",VLOOKUP(D38,Categorias!A:B,2,0))
B39: 46080 | E39: =IF(ISERROR(VLOOKUP(D39,Categorias!A:B,2,0)),"",VLOOKUP(D39,Categorias!A:B,2,0))
B40: 46081 | E40: =IF(ISERROR(VLOOKUP(D40,Categorias!A:B,2,0)),"",VLOOKUP(D40,Categorias!A:B,2,0))
B41: 46082 | E41: =IF(ISERROR(VLOOKUP(D41,Categorias!A:B,2,0)),"",VLOOKUP(D41,Categorias!A:B,2,0))
E42: =IF(ISERROR(VLOOKUP(D42,Categorias!A:B,2,0)),"",VLOOKUP(D42,Categorias!A:B,2,0))
E43: =IF(ISERROR(VLOOKUP(D43,Categorias!A:B,2,0)),"",VLOOKUP(D43,Categorias!A:B,2,0))
E44: =IF(ISERROR(VLOOKUP(D44,Categorias!A:B,2,0)),"",VLOOKUP(D44,Categorias!A:B,2,0))
E45: =IF(ISERROR(VLOOKUP(D45,Categorias!A:B,2,0)),"",VLOOKUP(D45,Categorias!A:B,2,0))
E46: =IF(ISERROR(VLOOKUP(D46,Categorias!A:B,2,0)),"",VLOOKUP(D46,Categorias!A:B,2,0))
E47: =IF(ISERROR(VLOOKUP(D47,Categorias!A:B,2,0)),"",VLOOKUP(D47,Categorias!A:B,2,0))
E48: =IF(ISERROR(VLOOKUP(D48,Categorias!A:B,2,0)),"",VLOOKUP(D48,Categorias!A:B,2,0))
E49: =IF(ISERROR(VLOOKUP(D49,Categorias!A:B,2,0)),"",VLOOKUP(D49,Categorias!A:B,2,0))
E50: =IF(ISERROR(VLOOKUP(D50,Categorias!A:B,2,0)),"",VLOOKUP(D50,Categorias!A:B,2,0))
...

Sheet MARÇO
B2: CONTROLE DE CAIXA
B7: SALDOS INICIAL: | G7: =D8+D9+D10+G8+G9+G10 -> 40
B8: BANCO 1: | E8: BANCO 4:
B9: BANCO 2: | E9: BANCO 5:
B10: BANCO 3: | E10: DINHEIRO EM ESPÉCIE: | G10: 40
B12: Data | C12: Descrição | D12: Categoria | E12: Fluxo de Caixa | F12: Entrada | G12: Saída | H12: Saldo
E13: =IF(ISERROR(VLOOKUP(D13,Categorias!A:B,2,0)),"",VLOOKUP(D13,Categorias!A:B,2,0)) | H13: =G7+F13-G13 -> 40
E14: =IF(ISERROR(VLOOKUP(D14,Categorias!A:B,2,0)),"",VLOOKUP(D14,Categorias!A:B,2,0)) | H14: =H13+F14-G14 -> 40
E15: =IF(ISERROR(VLOOKUP(D15,Categorias!A:B,2,0)),"",VLOOKUP(D15,Categorias!A:B,2,0)) | H15: =H14+F15-G15 -> 40
E16: =IF(ISERROR(VLOOKUP(D16,Categorias!A:B,2,0)),"",VLOOKUP(D16,Categorias!A:B,2,0)) | H16: =H15+F16-G16 -> 40
E17: =IF(ISERROR(VLOOKUP(D17,Categorias!A:B,2,0)),"",VLOOKUP(D17,Categorias!A:B,2,0)) | H17: =H16+F17-G17 -> 40
E18: =IF(ISERROR(VLOOKUP(D18,Categorias!A:B,2,0)),"",VLOOKUP(D18,Categorias!A:B,2,0)) | H18: =H17+F18-G18 -> 40
E19: =IF(ISERROR(VLOOKUP(D19,Categorias!A:B,2,0)),"",VLOOKUP(D19,Categorias!A:B,2,0)) | H19: =H18+F19-G19 -> 40
E20: =IF(ISERROR(VLOOKUP(D20,Categorias!A:B,2,0)),"",VLOOKUP(D20,Categorias!A:B,2,0)) | H20: =H19+F20-G20 -> 40
E21: =IF(ISERROR(VLOOKUP(D21,Categorias!A:B,2,0)),"",VLOOKUP(D21,Categorias!A:B,2,0)) | H21: =H20+F21-G21 -> 40
E22: =IF(ISERROR(VLOOKUP(D22,Categorias!A:B,2,0)),"",VLOOKUP(D22,Categorias!A:B,2,0)) | H22: =H21+F22-G22 -> 40
E23: =IF(ISERROR(VLOOKUP(D23,Categorias!A:B,2,0)),"",VLOOKUP(D23,Categorias!A:B,2,0)) | H23: =H22+F23-G23 -> 40
E24: =IF(ISERROR(VLOOKUP(D24,Categorias!A:B,2,0)),"",VLOOKUP(D24,Categorias!A:B,2,0)) | H24: =H23+F24-G24 -> 40
E25: =IF(ISERROR(VLOOKUP(D25,Categorias!A:B,2,0)),"",VLOOKUP(D25,Categorias!A:B,2,0)) | H25: =H24+F25-G25 -> 40
... E34: =IF(ISERROR(VLOOKUP(D34,Categorias!A:B,2,0)),"",VLOOKUP(D34,Categorias!A:B,2,0)) | H34: =H33+F34-G34 -> 40
E35: RECEITA | H35: =H34+F35-G35 -> 40
E36: =IF(ISERROR(VLOOKUP(D36,Categorias!A:B,2,0)),"",VLOOKUP(D36,Categorias!A:B,2,0)) | H36: =H35+F36-G36 -> 40
E37: =IF(ISERROR(VLOOKUP(D37,Categorias!A:B,2,0)),"",VLOOKUP(D37,Categorias!A:B,2,0)) | H37: =H36+F37-G37 -> 40
E38: =IF(ISERROR(VLOOKUP(D38,Categorias!A:B,2,0)),"",VLOOKUP(D38,Categorias!A:B,2,0)) | H38: =H37+F38-G38 -> 40
E39: =IF(ISERROR(VLOOKUP(D39,Categorias!A:B,2,0)),"",VLOOKUP(D39,Categorias!A:B,2,0)) | H39: =H38+F39-G39 -> 40
E40: =IF(ISERROR(VLOOKUP(D40,Categorias!A:B,2,0)),"",VLOOKUP(D40,Categorias!A:B,2,0)) | H40: =H39+F40-G40 -> 40
E41: =IF(ISERROR(VLOOKUP(D41,Categorias!A:B,2,0)),"",VLOOKUP(D41,Categorias!A:B,2,0)) | H41: =H40+F41-G41 -> 40
E42: =IF(ISERROR(VLOOKUP(D42,Categorias!A:B,2,0)),"",VLOOKUP(D42,Categorias!A:B,2,0)) | H42: =H41+F42-G42 -> 40
E43: =IF(ISERROR(VLOOKUP(D43,Categorias!A:B,2,0)),"",VLOOKUP(D43,Categorias!A:B,2,0)) | H43: =H42+F43-G43 -> 40
E44: DESPESAS FIXAS | H44: =H43+F44-G44 -> 40
E45: =IF(ISERROR(VLOOKUP(D45,Categorias!A:B,2,0)),"",VLOOKUP(D45,Categorias!A:B,2,0)) | H45: =H44+F45-G45 -> 40
E46: =IF(ISERROR(VLOOKUP(D46,Categorias!A:B,2,0)),"",VLOOKUP(D46,Categorias!A:B,2,0)) | H46: =H45+F46-G46 -> 40
E47: =IF(ISERROR(VLOOKUP(D47,Categorias!A:B,2,0)),"",VLOOKUP(D47,Categorias!A:B,2,0)) | H47: =H46+F47-G47 -> 40
E48: =IF(ISERROR(VLOOKUP(D48,Categorias!A:B,2,0)),"",VLOOKUP(D48,Categorias!A:B,2,0)) | H48: =H47+F48-G48 -> 40
E49: =IF(ISERROR(VLOOKUP(D49,Categorias!A:B,2,0)),"",VLOOKUP(D49,Categorias!A:B,2,0)) | H49: =H48+F49-G49 -> 40
E50: =IF(ISERROR(VLOOKUP(D50,Categorias!A:B,2,0)),"",VLOOKUP(D50,Categorias!A:B,2,0)) | H50: =H49+F50-G50 -> 40
E51: =IF(ISERROR(VLOOKUP(D51,Categorias!A:B,2,0)),"",VLOOKUP(D51,Categorias!A:B,2,0)) | H51: =H50+F51-G51 -> 40
E52: =IF(ISERROR(VLOOKUP(D52,Categorias!A:B,2,0)),"",VLOOKUP(D52,Categorias!A:B,2,0)) | H52: =H51+F52-G52 -> 40
E53: =IF(ISERROR(VLOOKUP(D53,Categorias!A:B,2,0)),"",VLOOKUP(D53,Categorias!A:B,2,0)) | H53: =H52+F53-G53 -> 40
E54: =IF(ISERROR(VLOOKUP(D54,Categorias!A:B,2,0)),"",VLOOKUP(D54,Categorias!A:B,2,0)) | H54: =H53+F54-G54 -> 40
...

Sheet ABRIL
B2: CONTROLE DE CAIXA
B7: SALDOS INICIAL: | G7: =D8+D9+D10+G8+G9+G10 -> 0
B8: BANCO 1: | E8: BANCO 4:
B9: BANCO 2: | E9: BANCO 5:
B10: BANCO 3: | E10: DINHEIRO EM ESPÉCIE:
B12: Data | C12: Descrição | D12: Categoria | E12: Fluxo de Caixa | F12: Entrada | G12: Saída | H12: Saldo
E13: =IF(ISERROR(VLOOKUP(D13,Categorias!A:B,2,0)),"",VLOOKUP(D13,Categorias!A:B,2,0)) | H13: =G7+F13-G13 -> 0
E14: =IF(ISERROR(VLOOKUP(D14,Categorias!A:B,2,0)),"",VLOOKUP(D14,Categorias!A:B,2,0)) | H14: =H13+F14-G14 -> 0
E15: =IF(ISERROR(VLOOKUP(D15,Categorias!A:B,2,0)),"",VLOOKUP(D15,Categorias!A:B,2,0)) | H15: =H14+F15-G15 -> 0
E16: =IF(ISERROR(VLOOKUP(D16,Categorias!A:B,2,0)),"",VLOOKUP(D16,Categorias!A:B,2,0)) | H16: =H15+F16-G16 -> 0
E17: =IF(ISERROR(VLOOKUP(D17,Categorias!A:B,2,0)),"",VLOOKUP(D17,Categorias!A:B,2,0)) | H17: =H16+F17-G17 -> 0
E18: =IF(ISERROR(VLOOKUP(D18,Categorias!A:B,2,0)),"",VLOOKUP(D18,Categorias!A:B,2,0)) | H18: =H17+F18-G18 -> 0
H19: =H18+F19-G19 -> 0
E20: =IF(ISERROR(VLOOKUP(D20,Categorias!A:B,2,0)),"",VLOOKUP(D20,Categorias!A:B,2,0)) | H20: =H19+F20-G20 -> 0
E21: =IF(ISERROR(VLOOKUP(D21,Categorias!A:B,2,0)),"",VLOOKUP(D21,Categorias!A:B,2,0)) | H21: =H20+F21-G21 -> 0
E22: =IF(ISERROR(VLOOKUP(D22,Categorias!A:B,2,0)),"",VLOOKUP(D22,Categorias!A:B,2,0)) | H22: =H21+F22-G22 -> 0
E23: =IF(ISERROR(VLOOKUP(D23,Categorias!A:B,2,0)),"",VLOOKUP(D23,Categorias!A:B,2,0)) | H23: =H22+F23-G23 -> 0
E24: =IF(ISERROR(VLOOKUP(D24,Categorias!A:B,2,0)),"",VLOOKUP(D24,Categorias!A:B,2,0)) | H24: =H23+F24-G24 -> 0
E25: =IF(ISERROR(VLOOKUP(D25,Categorias!A:B,2,0)),"",VLOOKUP(D25,Categorias!A:B,2,0)) | H25: =H24+F25-G25 -> 0
E26: =IF(ISERROR(VLOOKUP(D26,Categorias!A:B,2,0)),"",VLOOKUP(D26,Categorias!A:B,2,0)) | H26: =H25+F26-G26 -> 0
E27: =IF(ISERROR(VLOOKUP(D27,Categorias!A:B,2,0)),"",VLOOKUP(D27,Categorias!A:B,2,0)) | H27: =H26+F27-G27 -> 0
E28: =IF(ISERROR(VLOOKUP(D28,Categorias!A:B,2,0)),"",VLOOKUP(D28,Categorias!A:B,2,0)) | H28: =H27+F28-G28 -> 0
E29: =IF(ISERROR(VLOOKUP(D29,Categorias!A:B,2,0)),"",VLOOKUP(D29,Categorias!A:B,2,0)) | H29: =H28+F29-G29 -> 0
E30: =IF(ISERROR(VLOOKUP(D30,Categorias!A:B,2,0)),"",VLOOKUP(D30,Categorias!A:B,2,0)) | H30: =H29+F30-G30 -> 0
E31: =IF(ISERROR(VLOOKUP(D31,Categorias!A:B,2,0)),"",VLOOKUP(D31,Categorias!A:B,2,0)) | H31: =H30+F31-G31 -> 0
... E257: =IF(ISERROR(VLOOKUP(D257,Categorias!A:B,2,0)),"",VLOOKUP(D257,Categorias!A:B,2,0)) | H257: =H256+F257-G257 -> 0

Sheet MAIO
B2: CONTROLE DE CAIXA
B7: SALDOS INICIAL: | G7: =D8+D9+D10+G8+G9+G10 -> 329.64
B8: BANCO 1: | D8: 329.64 | E8: BANCO 4:
B9: BANCO 2: | E9: BANCO 5:
B10: BANCO 3: | E10: DINHEIRO EM ESPÉCIE:
B12: Data | C12: Descrição | D12: Categoria | E12: Fluxo de Caixa | F12: Entrada | G12: Saída | H12: Saldo
B13: 31/05/2026 | C13: Lucas Freire Tavares Braga | D13: Fornecedor | E13: DESPESA | G13: 1008 | H13: =G7+F13-G13 -> -678.36
B14: 31/05/2026 | C14: Otavio Junqueira Esteves Jardim | D14: Troco e devolução | E14: =IF(ISERROR(VLOOKUP(D14,Categorias!A:B,2,0)),"",VLOOKUP(D14,Categorias!A:B,2,0)) -> NÃO OPERACIONAL | G14: 3 | H14: =H13+F14-G14 -> -681.36
B15: 31/05/2026 | C15: MARCELO JUNQUEIRA MACEDO | D15: Recebimento de venda | E15: =IF(ISERROR(VLOOKUP(D15,Categorias!A:B,2,0)),"",VLOOKUP(D15,Categorias!A:B,2,0)) -> RECEITA | F15: 57 | H15: =H14+F15-G15 -> -624.36
B16: 31/05/2026 | C16: Queila Klein Cardoso | D16: Recebimento de venda | E16: =IF(ISERROR(VLOOKUP(D16,Categorias!A:B,2,0)),"",VLOOKUP(D16,Categorias!A:B,2,0)) -> RECEITA | F16: 25 | H16: =H15+F16-G16 -> -599.36
B17: 31/05/2026 | C17: HELENA KLEIN GALVAO ROCHA | D17: Troco e devolução | E17: =IF(ISERROR(VLOOKUP(D17,Categorias!A:B,2,0)),"",VLOOKUP(D17,Categorias!A:B,2,0)) -> NÃO OPERACIONAL | G17: 75 | H17: =H16+F17-G17 -> -674.36
B18: 31/05/2026 | C18: Everton Prado Caldeira Fernandes | D18: Troco e devolução | E18: =IF(ISERROR(VLOOKUP(D18,Categorias!A:B,2,0)),"",VLOOKUP(D18,Categorias!A:B,2,0)) -> NÃO OPERACIONAL | G18: 25 | H18: =H17+F18-G18 -> -699.36
B19: 31/05/2026 | C19: ISABELA SIQUEIRA QUADROS | D19: Troco e devolução | E19: =IF(ISERROR(VLOOKUP(D19,Categorias!A:B,2,0)),"",VLOOKUP(D19,Categorias!A:B,2,0)) -> NÃO OPERACIONAL | G19: 18 | H19: =H18+F19-G19 -> -717.36
B20: 31/05/2026 | C20: Julio Galvao Dias | D20: Recebimento de venda | E20: =IF(ISERROR(VLOOKUP(D20,Categorias!A:B,2,0)),"",VLOOKUP(D20,Categorias!A:B,2,0)) -> RECEITA | F20: 25 | H20: =H19+F20-G20 -> -692.36
B21: 31/05/2026 | C21: CESAR PRADO DANTAS | D21: Troco e devolução | E21: =IF(ISERROR(VLOOKUP(D21,Categorias!A:B,2,0)),"",VLOOKUP(D21,Categorias!A:B,2,0)) -> NÃO OPERACIONAL | G21: 25 | H21: =H20+F21-G21 -> -717.36
B22: 31/05/2026 | C22: Elisa Duarte Freire | D22: Recebimento de venda | E22: =IF(ISERROR(VLOOKUP(D22,Categorias!A:B,2,0)),"",VLOOKUP(D22,Categorias!A:B,2,0)) -> RECEITA | F22: 25 | H22: =H21+F22-G22 -> -692.36
B23: 31/05/2026 | C23: KARINA ZANETTI ROCHA GALVAO | D23: Recebimento de venda | E23: =IF(ISERROR(VLOOKUP(D23,Categorias!A:B,2,0)),"",VLOOKUP(D23,Categorias!A:B,2,0)) -> RECEITA | F23: 50 | H23: =H22+F23-G23 -> -642.36
B24: 31/05/2026 | C24: VINICIUS CALDEIRA HORTA | D24: Recebimento de venda | E24: =IF(ISERROR(VLOOKUP(D24,Categorias!A:B,2,0)),"",VLOOKUP(D24,Categorias!A:B,2,0)) -> RECEITA | F24: 25 | H24: =H23+F24-G24 -> -617.36
B25: 31/05/2026 | C25: Rafael Rocha Salgado | D25: Troco e devolução | E25: =IF(ISERROR(VLOOKUP(D25,Categorias!A:B,2,0)),"",VLOOKUP(D25,Categorias!A:B,2,0)) -> NÃO OPERACIONAL | G25: 28 | H25: =H24+F25-G25 -> -645.36
B26: 31/05/2026 | C26: Rafael Rocha Salgado | D26: Recebimento de venda | E26: =IF(ISERROR(VLOOKUP(D26,Categorias!A:B,2,0)),"",VLOOKUP(D26,Categorias!A:B,2,0)) -> RECEITA | F26: 53 | H26: =H25+F26-G26 -> -592.36
B27: 31/05/2026 | C27: Rafael Rocha Salgado | D27: Recebimento de venda | E27: =IF(ISERROR(VLOOKUP(D27,Categorias!A:B,2,0)),"",VLOOKUP(D27,Categorias!A:B,2,0)) -> RECEITA | F27: 53 | H27: =H26+F27-G27 -> -539.36
B28: 31/05/2026 | C28: TOMAS NEVES TAVARES DUARTE | D28: Recebimento de venda | E28: =IF(ISERROR(VLOOKUP(D28,Categorias!A:B,2,0)),"",VLOOKUP(D28,Categorias!A:B,2,0)) -> RECEITA | F28: 25 | H28: =H27+F28-G28 -> -514.36
B29: 30/05/2026 | C29: Wanda Lemos Tavares Horta | D29: Motoboys | E29: =IF(ISERROR(VLOOKUP(D29,Categorias!A:B,2,0)),"",VLOOKUP(D29,Categorias!A:B,2,0)) -> GASTOS VARIÁVEIS | G29: 90 | H29: =H28+F29-G29 -> -604.36
B30: 30/05/2026 | C30: QUEILA CARDOSO SIQUEIRA DANTAS | D30: Recebimento de venda | E30: =IF(ISERROR(VLOOKUP(D30,Categorias!A:B,2,0)),"",VLOOKUP(D30,Categorias!A:B,2,0)) -> RECEITA | F30: 50 | H30: =H29+F30-G30 -> -554.36
B31: 30/05/2026 | C31: EMANUEL OLIVEIRA MACEDO MACEDO | D31: Recebimento de venda | E31: =IF(ISERROR(VLOOKUP(D31,Categorias!A:B,2,0)),"",VLOOKUP(D31,Categorias!A:B,2,0)) -> RECEITA | F31: 25 | H31: =H30+F31-G31 -> -529.36
B32: 30/05/2026 | C32: Julio Bastos Lemos Andrade | D32: Recebimento de venda | E32: =IF(ISERROR(VLOOKUP(D32,Categorias!A:B,2,0)),"",VLOOKUP(D32,Categorias!A:B,2,0)) -> RECEITA | F32: 25 | H32: =H31+F32-G32 -> -504.36
B33: 30/05/2026 | C33: Everton Prado Caldeira Fernandes | D33: Troco e devolução | E33: =IF(ISERROR(VLOOKUP(D33,Categorias!A:B,2,0)),"",VLOOKUP(D33,Categorias!A:B,2,0)) -> NÃO OPERACIONAL | G33: 17 | H33: =H32+F33-G33 -> -521.36
B34: 30/05/2026 | C34: DIEGO KLEIN FREIRE | D34: Recebimento de venda | E34: =IF(ISERROR(VLOOKUP(D34,Categorias!A:B,2,0)),"",VLOOKUP(D34,Categorias!A:B,2,0)) -> RECEITA | F34: 25 | H34: =H33+F34-G34 -> -496.36
B35: 30/05/2026 | C35: Natalia Almeida Tavares | D35: Recebimento de venda | E35: =IF(ISERROR(VLOOKUP(D35,Categorias!A:B,2,0)),"",VLOOKUP(D35,Categorias!A:B,2,0)) -> RECEITA | F35: 25 | H35: =H34+F35-G35 -> -471.36
B36: 30/05/2026 | C36: LUCAS QUADROS ANDRADE | D36: Recebimento de venda | E36: =IF(ISERROR(VLOOKUP(D36,Categorias!A:B,2,0)),"",VLOOKUP(D36,Categorias!A:B,2,0)) -> RECEITA | F36: 10 | H36: =H35+F36-G36 -> -461.36
B37: 30/05/2026 | C37: LUCAS QUADROS ANDRADE | D37: Recebimento de venda | E37: =IF(ISERROR(VLOOKUP(D37,Categorias!A:B,2,0)),"",VLOOKUP(D37,Categorias!A:B,2,0)) -> RECEITA | F37: 25 | H37: =H36+F37-G37 -> -436.36
B38: 30/05/2026 | C38: Julio Freire Quadros Andrade | D38: Recebimento de venda | E38: =IF(ISERROR(VLOOKUP(D38,Categorias!A:B,2,0)),"",VLOOKUP(D38,Categorias!A:B,2,0)) -> RECEITA | F38: 25 | H38: =H37+F38-G38 -> -411.36
B39: 30/05/2026 | C39: RAFAEL DIAS DUARTE | D39: Recebimento de venda | E39: =IF(ISERROR(VLOOKUP(D39,Categorias!A:B,2,0)),"",VLOOKUP(D39,Categorias!A:B,2,0)) -> RECEITA | F39: 25 | H39: =H38+F39-G39 -> -386.36
B40: 30/05/2026 | C40: TOMAS NEVES TAVARES DUARTE | D40: Recebimento de venda | E40: =IF(ISERROR(VLOOKUP(D40,Categorias!A:B,2,0)),"",VLOOKUP(D40,Categorias!A:B,2,0)) -> RECEITA | F40: 50 | H40: =H39+F40-G40 -> -336.36
B41: 30/05/2026 | C41: JULIO ROCHA IBRAHIM GUIMARAES | D41: Recebimento de venda | E41: =IF(ISERROR(VLOOKUP(D41,Categorias!A:B,2,0)),"",VLOOKUP(D41,Categorias!A:B,2,0)) -> RECEITA | F41: 50 | H41: =H40+F41-G41 -> -286.36
B42: 30/05/2026 | C42: Wagner Fernandes Neves | D42: Recebimento de venda | E42: =IF(ISERROR(VLOOKUP(D42,Categorias!A:B,2,0)),"",VLOOKUP(D42,Categorias!A:B,2,0)) -> RECEITA | F42: 25 | H42: =H41+F42-G42 -> -261.36
B43: 29/05/2026 | C43: URSULA MORAES BARBOSA VASCONCELOS | D43: Fornecedor | E43: =IF(ISERROR(VLOOKUP(D43,Categorias!A:B,2,0)),"",VLOOKUP(D43,Categorias!A:B,2,0)) -> GASTOS VARIÁVEIS | G43: 75.59 | H43: =H42+F43-G43 -> -336.95
B44: 29/05/2026 | C44: BRUNO CARDOSO MORAES ANDRADE | D44: Marketing | E44: =IF(ISERROR(VLOOKUP(D44,Categorias!A:B,2,0)),"",VLOOKUP(D44,Categorias!A:B,2,0)) -> INVESTIMENTOS | G44: 180 | H44: =H43+F44-G44 -> -516.95
B45: 29/05/2026 | C45: Rafael Queiroz Macedo Barbosa | D45: Troco e devolução | E45: =IF(ISERROR(VLOOKUP(D45,Categorias!A:B,2,0)),"",VLOOKUP(D45,Categorias!A:B,2,0)) -> NÃO OPERACIONAL | G45: 18 | H45: =H44+F45-G45 -> -534.95
B46: 29/05/2026 | C46: GIOVANA JARDIM DANTAS ESTEVES | D46: Fornecedor | E46: =IF(ISERROR(VLOOKUP(D46,Categorias!A:B,2,0)),"",VLOOKUP(D46,Categorias!A:B,2,0)) -> GASTOS VARIÁVEIS | G46: 300 | H46: =H45+F46-G46 -> -834.95
...

Sheet JUNHO
B2: CONTROLE DE CAIXA
B7: SALDOS INICIAL: | G7: =D8+D9+D10+G8+G9+G10 -> 952.71
B8: BANCO 1: | D8: 952.71 | E8: BANCO 4:
B9: BANCO 2: | E9: BANCO 5:
B10: BANCO 3: | E10: DINHEIRO EM ESPÉCIE:
B12: Data | C12: Descrição | D12: Categoria | E12: Fluxo de Caixa | F12: Entrada | G12: Saída | H12: Saldo
B13: 46174 | C13: RECEBIBMENTO ANTECIPAÇÃO VENDAS | D13: Recebimento de venda | E13: =IF(ISERROR(VLOOKUP(D13,Categorias!A:B,2,0)),"",VLOOKUP(D13,Categorias!A:B,2,0)) -> RECEITA | F13: 74.12 | H13: =G7+F13-G13 -> 1026.83
B14: 17/06/2026 | C14: Pix - Heitor Neves Horta | D14: Recebimento de venda | E14: =IF(ISERROR(VLOOKUP(D14,Categorias!A:B,2,0)),"",VLOOKUP(D14,Categorias!A:B,2,0)) -> RECEITA
B15: 17/06/2026 | C15: Pix - PATRICIA ANDRADE BARBOSA HORTA | D15: Recebimento de venda | E15: =IF(ISERROR(VLOOKUP(D15,Categorias!A:B,2,0)),"",VLOOKUP(D15,Categorias!A:B,2,0)) -> RECEITA | F15: 50 | H15: =H13+F15-G15 -> 1076.83
B16: 17/06/2026 | C16: Pix - Cesar Quadros Tavares Siqueira | D16: Recebimento de venda | E16: =IF(ISERROR(VLOOKUP(D16,Categorias!A:B,2,0)),"",VLOOKUP(D16,Categorias!A:B,2,0)) -> RECEITA | F16: 50 | H16: =H15+F16-G16 -> 1126.83
B17: 17/06/2026 | C17: Pix - FABIO SIQUEIRA VASCONCELOS ZANETTI | D17: Recebimento de venda | E17: =IF(ISERROR(VLOOKUP(D17,Categorias!A:B,2,0)),"",VLOOKUP(D17,Categorias!A:B,2,0)) -> RECEITA | F17: 30 | H17: =H16+F17-G17 -> 1156.83
B18: 17/06/2026 | C18: Maquininha - Rafael Dias Duarte | D18: Recebimento de venda | E18: =IF(ISERROR(VLOOKUP(D18,Categorias!A:B,2,0)),"",VLOOKUP(D18,Categorias!A:B,2,0)) -> RECEITA | F18: 25 | H18: =H17+F18-G18 -> 1181.83
B19: 17/06/2026 | C19: Maquininha - Tomas Tavares Junqueira Macedo | D19: Recebimento de venda | E19: =IF(ISERROR(VLOOKUP(D19,Categorias!A:B,2,0)),"",VLOOKUP(D19,Categorias!A:B,2,0)) -> RECEITA | F19: 58 | H19: =H18+F19-G19 -> 1239.83
B20: 17/06/2026 | C20: Pix - EVERTON IBRAHIM JARDIM MORAES | D20: Recebimento de venda | E20: =IF(ISERROR(VLOOKUP(D20,Categorias!A:B,2,0)),"",VLOOKUP(D20,Categorias!A:B,2,0)) -> RECEITA | F20: 25 | H20: =H19+F20-G20 -> 1264.83
B21: 17/06/2026 | C21: Pix - Alexandre Braga Esteves Teixeira | D21: Recebimento de venda | E21: =IF(ISERROR(VLOOKUP(D21,Categorias!A:B,2,0)),"",VLOOKUP(D21,Categorias!A:B,2,0)) -> RECEITA | F21: 25 | H21: =H20+F21-G21 -> 1289.83
B22: 17/06/2026 | C22: Pix - ULISSES MACEDO AMARAL | D22: Recebimento de venda | E22: =IF(ISERROR(VLOOKUP(D22,Categorias!A:B,2,0)),"",VLOOKUP(D22,Categorias!A:B,2,0)) -> RECEITA | F22: 50 | H22: =H21+F22-G22 -> 1339.83
B23: 17/06/2026 | C23: Antecipação de Crédito | D23: Recebimento de venda | E23: =IF(ISERROR(VLOOKUP(D23,Categorias!A:B,2,0)),"",VLOOKUP(D23,Categorias!A:B,2,0)) -> RECEITA | F23: 29.46 | H23: =H22+F23-G23 -> 1369.29
B24: 18/06/2026 | C24: Maquininha - NADIA LACERDA FONTES CALDEIRA | D24: Recebimento de venda | E24: =IF(ISERROR(VLOOKUP(D24,Categorias!A:B,2,0)),"",VLOOKUP(D24,Categorias!A:B,2,0)) -> RECEITA | F24: 30 | H24: =H23+F24-G24 -> 1399.29
B25: 18/06/2026 | C25: Cartão Débito - Elo | D25: Recebimento de venda | E25: =IF(ISERROR(VLOOKUP(D25,Categorias!A:B,2,0)),"",VLOOKUP(D25,Categorias!A:B,2,0)) -> RECEITA | F25: 24.26 | H25: =H24+F25-G25 -> 1423.55
B26: 19/06/2026 | C26: Maquininha - Beatriz Pacheco Horta | D26: Recebimento de venda | E26: =IF(ISERROR(VLOOKUP(D26,Categorias!A:B,2,0)),"",VLOOKUP(D26,Categorias!A:B,2,0)) -> RECEITA | F26: 25 | H26: =H25+F26-G26 -> 1448.55
B27: 19/06/2026 | C27: Pix - PATRICIA GALVAO LEMOS | D27: Recebimento de venda | E27: =IF(ISERROR(VLOOKUP(D27,Categorias!A:B,2,0)),"",VLOOKUP(D27,Categorias!A:B,2,0)) -> RECEITA | F27: 25 | H27: =H26+F27-G27 -> 1473.55
... B44: 21/06/2026 | C44: Pix - BERNARDO GUIMARAES COUTINHO | D44: Recebimento de venda | E44: =IF(ISERROR(VLOOKUP(D44,Categorias!A:B,2,0)),"",VLOOKUP(D44,Categorias!A:B,2,0)) -> RECEITA | F44: 25 | H44: =H43+F44-G44 -> 1976.86
B45: 21/06/2026 | C45: Maquininha - PAULO VALENTE FONTES ZANETTI | D45: Recebimento de venda | E45: RECEITA | F45: 7 | H45: =H44+F45-G45 -> 1983.86
B46: 21/06/2026 | C46: Pix - FERNANDA COUTINHO HENRIQUES SALGADO | D46: Recebimento de venda | E46: =IF(ISERROR(VLOOKUP(D46,Categorias!A:B,2,0)),"",VLOOKUP(D46,Categorias!A:B,2,0)) -> RECEITA | F46: 25 | H46: =H45+F46-G46 -> 2008.86
B47: 21/06/2026 | C47: Maquininha - LARISSA MORAES OLIVEIRA | D47: Recebimento de venda | E47: =IF(ISERROR(VLOOKUP(D47,Categorias!A:B,2,0)),"",VLOOKUP(D47,Categorias!A:B,2,0)) -> RECEITA | F47: 35 | H47: =H46+F47-G47 -> 2043.86
B48: 21/06/2026 | C48: Pix - RAFAEL VASCONCELOS FERNANDES | D48: Recebimento de venda | E48: =IF(ISERROR(VLOOKUP(D48,Categorias!A:B,2,0)),"",VLOOKUP(D48,Categorias!A:B,2,0)) -> RECEITA | F48: 32 | H48: =H47+F48-G48 -> 2075.86
B49: 21/06/2026 | C49: Pix - Vinicius Fernandes Rocha Siqueira | D49: Recebimento de venda | E49: =IF(ISERROR(VLOOKUP(D49,Categorias!A:B,2,0)),"",VLOOKUP(D49,Categorias!A:B,2,0)) -> RECEITA | F49: 31 | H49: =H48+F49-G49 -> 2106.86
B50: 21/06/2026 | C50: Maquininha - BRUNO SALGADO DUARTE FERNANDES | D50: Recebimento de venda | E50: =IF(ISERROR(VLOOKUP(D50,Categorias!A:B,2,0)),"",VLOOKUP(D50,Categorias!A:B,2,0)) -> RECEITA | F50: 45 | H50: =H49+F50-G50 -> 2151.86
B51: 21/06/2026 | C51: Maquininha - Eduarda Teixeira Barbosa Coutinho | D51: Recebimento de venda | E51: =IF(ISERROR(VLOOKUP(D51,Categorias!A:B,2,0)),"",VLOOKUP(D51,Categorias!A:B,2,0)) -> RECEITA | F51: 5 | H51: =H50+F51-G51 -> 2156.86
B52: 21/06/2026 | C52: Maquininha - OSCAR VALENTE TEIXEIRA ESTEVES | D52: Recebimento de venda | E52: =IF(ISERROR(VLOOKUP(D52,Categorias!A:B,2,0)),"",VLOOKUP(D52,Categorias!A:B,2,0)) -> RECEITA | F52: 72 | H52: =H51+F52-G52 -> 2228.86
B53: 21/06/2026 | C53: Maquininha - Kevin Queiroz Coutinho | D53: Recebimento de venda | E53: =IF(ISERROR(VLOOKUP(D53,Categorias!A:B,2,0)),"",VLOOKUP(D53,Categorias!A:B,2,0)) -> RECEITA | F53: 5 | H53: =H52+F53-G53 -> 2233.86
B54: 22/06/2026 | C54: Pix - Juliana Pacheco Nogueira Cardoso | D54: Recebimento de venda | E54: =IF(ISERROR(VLOOKUP(D54,Categorias!A:B,2,0)),"",VLOOKUP(D54,Categorias!A:B,2,0)) -> RECEITA | F54: 32 | H54: =H53+F54-G54 -> 2265.86
B55: 22/06/2026 | C55: Pix - Everton Prado Caldeira Fernandes | D55: Recebimento de venda | E55: =IF(ISERROR(VLOOKUP(D55,Categorias!A:B,2,0)),"",VLOOKUP(D55,Categorias!A:B,2,0)) -> RECEITA | F55: 30 | H55: =H54+F55-G55 -> 2295.86
B56: 22/06/2026 | C56: Pix - FERNANDA COUTINHO HENRIQUES SALGADO | D56: Recebimento de venda | E56: =IF(ISERROR(VLOOKUP(D56,Categorias!A:B,2,0)),"",VLOOKUP(D56,Categorias!A:B,2,0)) -> RECEITA | F56: 25 | H56: =H55+F56-G56 -> 2320.86
B57: 22/06/2026 | C57: Pix - Alexandre Braga Esteves Teixeira | D57: Recebimento de venda | E57: =IF(ISERROR(VLOOKUP(D57,Categorias!A:B,2,0)),"",VLOOKUP(D57,Categorias!A:B,2,0)) -> RECEITA | F57: 50 | H57: =H56+F57-G57 -> 2370.86
... B77: 24/06/2026 | C77: Pix - Alexandre Horta Zanetti | D77: Recebimento de venda | E77: =IF(ISERROR(VLOOKUP(D77,Categorias!A:B,2,0)),"",VLOOKUP(D77,Categorias!A:B,2,0)) -> RECEITA | F77: 25 | H77: =H76+F77-G77 -> 3362.64
B78: 17/06/2026 | C78: Pix - Wanda Lemos Tavares Horta | D78: Motoboys | E78: =IF(ISERROR(VLOOKUP(D78,Categorias!A:B,2,0)),"",VLOOKUP(D78,Categorias!A:B,2,0)) -> GASTOS VARIÁVEIS | G78: 57 | H78: =H77+F78-G78 -> 3305.64
B79: 17/06/2026 | C79: Tarifa bancária | D79: Taxa de cartão | E79: =IF(ISERROR(VLOOKUP(D79,Categorias!A:B,2,0)),"",VLOOKUP(D79,Categorias!A:B,2,0)) -> GASTOS VARIÁVEIS | G79: 0.24 | H79: =H78+F79-G79 -> 3305.4
B80: 17/06/2026 | C80: Tarifa bancária | D80: Taxa de cartão | E80: =IF(ISERROR(VLOOKUP(D80,Categorias!A:B,2,0)),"",VLOOKUP(D80,Categorias!A:B,2,0)) -> GASTOS VARIÁVEIS | G80: 0.57 | H80: =H79+F80-G80 -> 3304.83
B81: 18/06/2026 | C81: Tarifa bancária | D81: Taxa de cartão | E81: =IF(ISERROR(VLOOKUP(D81,Categorias!A:B,2,0)),"",VLOOKUP(D81,Categorias!A:B,2,0)) -> GASTOS VARIÁVEIS | G81: 0.29 | H81: =H80+F81-G81 -> 3304.54
...

Sheet JULHO
B2: CONTROLE DE CAIXA
B7: SALDOS INICIAL: | G7: =D8+D9+D10+G8+G9+G10 -> 0
B8: BANCO 1: | E8: BANCO 4:
B9: BANCO 2: | E9: BANCO 5:
B10: BANCO 3: | E10: DINHEIRO EM ESPÉCIE:
B12: Data | C12: Descrição | D12: Categoria | E12: Fluxo de Caixa | F12: Entrada | G12: Saída | H12: Saldo
B13: 46210 | C13: Renato Barbosa Rocha Ibrahim | E13: =IF(ISERROR(VLOOKUP(D13,Categorias!A:B,2,0)),"",VLOOKUP(D13,Categorias!A:B,2,0)) | F13: 1234.56 | H13: =G7+F13-G13 -> 0
B14: 46210 | C14: Rodrigo Dantas | E14: =IF(ISERROR(VLOOKUP(D14,Categorias!A:B,2,0)),"",VLOOKUP(D14,Categorias!A:B,2,0)) | G14: 0.56 | H14: =H13+F14-G14 -> 0
B15: 46223 | C15: Alice Almeida | E15: =IF(ISERROR(VLOOKUP(D15,Categorias!A:B,2,0)),"",VLOOKUP(D15,Categorias!A:B,2,0)) | G15: 350 | H15: =H14+F15-G15 -> 0
E16: =IF(ISERROR(VLOOKUP(D16,Categorias!A:B,2,0)),"",VLOOKUP(D16,Categorias!A:B,2,0)) | H16: =H15+F16-G16 -> 0
E17: =IF(ISERROR(VLOOKUP(D17,Categorias!A:B,2,0)),"",VLOOKUP(D17,Categorias!A:B,2,0)) | H17: =H16+F17-G17 -> 0
E18: =IF(ISERROR(VLOOKUP(D18,Categorias!A:B,2,0)),"",VLOOKUP(D18,Categorias!A:B,2,0)) | H18: =H17+F18-G18 -> 0
E19: =IF(ISERROR(VLOOKUP(D19,Categorias!A:B,2,0)),"",VLOOKUP(D19,Categorias!A:B,2,0)) | H19: =H18+F19-G19 -> 0
E20: =IF(ISERROR(VLOOKUP(D20,Categorias!A:B,2,0)),"",VLOOKUP(D20,Categorias!A:B,2,0)) | H20: =H19+F20-G20 -> 0
E21: =IF(ISERROR(VLOOKUP(D21,Categorias!A:B,2,0)),"",VLOOKUP(D21,Categorias!A:B,2,0)) | H21: =H20+F21-G21 -> 0
E22: =IF(ISERROR(VLOOKUP(D22,Categorias!A:B,2,0)),"",VLOOKUP(D22,Categorias!A:B,2,0)) | H22: =H21+F22-G22 -> 0
E23: =IF(ISERROR(VLOOKUP(D23,Categorias!A:B,2,0)),"",VLOOKUP(D23,Categorias!A:B,2,0)) | H23: =H22+F23-G23 -> 0
E24: =IF(ISERROR(VLOOKUP(D24,Categorias!A:B,2,0)),"",VLOOKUP(D24,Categorias!A:B,2,0)) | H24: =H23+F24-G24 -> 0
E25: =IF(ISERROR(VLOOKUP(D25,Categorias!A:B,2,0)),"",VLOOKUP(D25,Categorias!A:B,2,0)) | H25: =H24+F25-G25 -> 0
E26: =IF(ISERROR(VLOOKUP(D26,Categorias!A:B,2,0)),"",VLOOKUP(D26,Categorias!A:B,2,0)) | H26: =H25+F26-G26 -> 0
E27: =IF(ISERROR(VLOOKUP(D27,Categorias!A:B,2,0)),"",VLOOKUP(D27,Categorias!A:B,2,0)) | H27: =H26+F27-G27 -> 0
... E43: =IF(ISERROR(VLOOKUP(D43,Categorias!A:B,2,0)),"",VLOOKUP(D43,Categorias!A:B,2,0)) | H43: =H42+F43-G43 -> 0
H44: =H43+F44-G44 -> 0
E45: =IF(ISERROR(VLOOKUP(D45,Categorias!A:B,2,0)),"",VLOOKUP(D45,Categorias!A:B,2,0)) | H45: =H44+F45-G45 -> 0
E46: =IF(ISERROR(VLOOKUP(D46,Categorias!A:B,2,0)),"",VLOOKUP(D46,Categorias!A:B,2,0)) | H46: =H45+F46-G46 -> 0
E47: =IF(ISERROR(VLOOKUP(D47,Categorias!A:B,2,0)),"",VLOOKUP(D47,Categorias!A:B,2,0)) | H47: =H46+F47-G47 -> 0
E48: =IF(ISERROR(VLOOKUP(D48,Categorias!A:B,2,0)),"",VLOOKUP(D48,Categorias!A:B,2,0)) | H48: =H47+F48-G48 -> 0
E49: =IF(ISERROR(VLOOKUP(D49,Categorias!A:B,2,0)),"",VLOOKUP(D49,Categorias!A:B,2,0)) | H49: =H48+F49-G49 -> 0
E50: =IF(ISERROR(VLOOKUP(D50,Categorias!A:B,2,0)),"",VLOOKUP(D50,Categorias!A:B,2,0)) | H50: =H49+F50-G50 -> 0
E51: =IF(ISERROR(VLOOKUP(D51,Categorias!A:B,2,0)),"",VLOOKUP(D51,Categorias!A:B,2,0)) | H51: =H50+F51-G51 -> 0
E52: =IF(ISERROR(VLOOKUP(D52,Categorias!A:B,2,0)),"",VLOOKUP(D52,Categorias!A:B,2,0)) | H52: =H51+F52-G52 -> 0
E53: =IF(ISERROR(VLOOKUP(D53,Categorias!A:B,2,0)),"",VLOOKUP(D53,Categorias!A:B,2,0)) | H53: =H52+F53-G53 -> 0
E54: =IF(ISERROR(VLOOKUP(D54,Categorias!A:B,2,0)),"",VLOOKUP(D54,Categorias!A:B,2,0)) | H54: =H53+F54-G54 -> 0
E55: =IF(ISERROR(VLOOKUP(D55,Categorias!A:B,2,0)),"",VLOOKUP(D55,Categorias!A:B,2,0)) | H55: =H54+F55-G55 -> 0
E56: =IF(ISERROR(VLOOKUP(D56,Categorias!A:B,2,0)),"",VLOOKUP(D56,Categorias!A:B,2,0)) | H56: =H55+F56-G56 -> 0
... E254: =IF(ISERROR(VLOOKUP(D254,Categorias!A:B,2,0)),"",VLOOKUP(D254,Categorias!A:B,2,0)) | H254: =H253+F254-G254 -> 0

Sheet AGOSTO
B2: CONTROLE DE CAIXA
B7: SALDOS INICIAL: | G7: =D8+D9+D10+G8+G9+G10 -> 0
B8: BANCO 1: | E8: BANCO 4:
B9: BANCO 2: | E9: BANCO 5:
B10: BANCO 3: | E10: DINHEIRO EM ESPÉCIE:
B12: Data | C12: Descrição | D12: Categoria | E12: Fluxo de Caixa | F12: Entrada | G12: Saída | H12: Saldo
B13: 46237 | C13: Paulo Galvao Almeida | E13: =IF(ISERROR(VLOOKUP(D13,Categorias!A:B,2,0)),"",VLOOKUP(D13,Categorias!A:B,2,0)) | F13: 500 | H13: =G7+F13-G13 -> 0
B14: 46237 | C14: Camila Ramos Gomes Caldeira | E14: =IF(ISERROR(VLOOKUP(D14,Categorias!A:B,2,0)),"",VLOOKUP(D14,Categorias!A:B,2,0)) | F14: 89.9 | H14: =H13+F14-G14 -> 0
E15: =IF(ISERROR(VLOOKUP(D15,Categorias!A:B,2,0)),"",VLOOKUP(D15,Categorias!A:B,2,0)) | H15: =H14+F15-G15 -> 0
E16: =IF(ISERROR(VLOOKUP(D16,Categorias!A:B,2,0)),"",VLOOKUP(D16,Categorias!A:B,2,0)) | H16: =H15+F16-G16 -> 0
E17: =IF(ISERROR(VLOOKUP(D17,Categorias!A:B,2,0)),"",VLOOKUP(D17,Categorias!A:B,2,0)) | H17: =H16+F17-G17 -> 0
E18: =IF(ISERROR(VLOOKUP(D18,Categorias!A:B,2,0)),"",VLOOKUP(D18,Categorias!A:B,2,0)) | H18: =H17+F18-G18 -> 0
E19: =IF(ISERROR(VLOOKUP(D19,Categorias!A:B,2,0)),"",VLOOKUP(D19,Categorias!A:B,2,0)) | H19: =H18+F19-G19 -> 0
E20: =IF(ISERROR(VLOOKUP(D20,Categorias!A:B,2,0)),"",VLOOKUP(D20,Categorias!A:B,2,0)) | H20: =H19+F20-G20 -> 0
E21: =IF(ISERROR(VLOOKUP(D21,Categorias!A:B,2,0)),"",VLOOKUP(D21,Categorias!A:B,2,0)) | H21: =H20+F21-G21 -> 0
E22: =IF(ISERROR(VLOOKUP(D22,Categorias!A:B,2,0)),"",VLOOKUP(D22,Categorias!A:B,2,0)) | H22: =H21+F22-G22 -> 0
E23: =IF(ISERROR(VLOOKUP(D23,Categorias!A:B,2,0)),"",VLOOKUP(D23,Categorias!A:B,2,0)) | H23: =H22+F23-G23 -> 0
E24: =IF(ISERROR(VLOOKUP(D24,Categorias!A:B,2,0)),"",VLOOKUP(D24,Categorias!A:B,2,0)) | H24: =H23+F24-G24 -> 0
E25: =IF(ISERROR(VLOOKUP(D25,Categorias!A:B,2,0)),"",VLOOKUP(D25,Categorias!A:B,2,0)) | H25: =H24+F25-G25 -> 0
E26: =IF(ISERROR(VLOOKUP(D26,Categorias!A:B,2,0)),"",VLOOKUP(D26,Categorias!A:B,2,0)) | H26: =H25+F26-G26 -> 0
... E43: =IF(ISERROR(VLOOKUP(D43,Categorias!A:B,2,0)),"",VLOOKUP(D43,Categorias!A:B,2,0)) | H43: =H42+F43-G43 -> 0
H44: =H43+F44-G44 -> 0
E45: =IF(ISERROR(VLOOKUP(D45,Categorias!A:B,2,0)),"",VLOOKUP(D45,Categorias!A:B,2,0)) | H45: =H44+F45-G45 -> 0
E46: =IF(ISERROR(VLOOKUP(D46,Categorias!A:B,2,0)),"",VLOOKUP(D46,Categorias!A:B,2,0)) | H46: =H45+F46-G46 -> 0
E47: =IF(ISERROR(VLOOKUP(D47,Categorias!A:B,2,0)),"",VLOOKUP(D47,Categorias!A:B,2,0)) | H47: =H46+F47-G47 -> 0
E48: =IF(ISERROR(VLOOKUP(D48,Categorias!A:B,2,0)),"",VLOOKUP(D48,Categorias!A:B,2,0)) | H48: =H47+F48-G48 -> 0
E49: =IF(ISERROR(VLOOKUP(D49,Categorias!A:B,2,0)),"",VLOOKUP(D49,Categorias!A:B,2,0)) | H49: =H48+F49-G49 -> 0
E50: =IF(ISERROR(VLOOKUP(D50,Categorias!A:B,2,0)),"",VLOOKUP(D50,Categorias!A:B,2,0)) | H50: =H49+F50-G50 -> 0
E51: =IF(ISERROR(VLOOKUP(D51,Categorias!A:B,2,0)),"",VLOOKUP(D51,Categorias!A:B,2,0)) | H51: =H50+F51-G51 -> 0
E52: =IF(ISERROR(VLOOKUP(D52,Categorias!A:B,2,0)),"",VLOOKUP(D52,Categorias!A:B,2,0)) | H52: =H51+F52-G52 -> 0
E53: =IF(ISERROR(VLOOKUP(D53,Categorias!A:B,2,0)),"",VLOOKUP(D53,Categorias!A:B,2,0)) | H53: =H52+F53-G53 -> 0
E54: =IF(ISERROR(VLOOKUP(D54,Categorias!A:B,2,0)),"",VLOOKUP(D54,Categorias!A:B,2,0)) | H54: =H53+F54-G54 -> 0
E55: =IF(ISERROR(VLOOKUP(D55,Categorias!A:B,2,0)),"",VLOOKUP(D55,Categorias!A:B,2,0)) | H55: =H54+F55-G55 -> 0
E56: =IF(ISERROR(VLOOKUP(D56,Categorias!A:B,2,0)),"",VLOOKUP(D56,Categorias!A:B,2,0)) | H56: =H55+F56-G56 -> 0
... E254: =IF(ISERROR(VLOOKUP(D254,Categorias!A:B,2,0)),"",VLOOKUP(D254,Categorias!A:B,2,0)) | H254: =H253+F254-G254 -> 0

Sheet SETEMBRO
B2: CONTROLE DE CAIXA
B7: SALDOS INICIAL: | G7: =D8+D9+D10+G8+G9+G10 -> 0
B8: BANCO 1: | E8: BANCO 4:
B9: BANCO 2: | E9: BANCO 5:
B10: BANCO 3: | E10: DINHEIRO EM ESPÉCIE:
B12: Data | C12: Descrição | D12: Categoria | E12: Fluxo de Caixa | F12: Entrada | G12: Saída | H12: Saldo
E13: =IF(ISERROR(VLOOKUP(D13,Categorias!A:B,2,0)),"",VLOOKUP(D13,Categorias!A:B,2,0)) | H13: =G7+F13-G13 -> 0
E14: =IF(ISERROR(VLOOKUP(D14,Categorias!A:B,2,0)),"",VLOOKUP(D14,Categorias!A:B,2,0)) | H14: =H13+F14-G14 -> 0
E15: =IF(ISERROR(VLOOKUP(D15,Categorias!A:B,2,0)),"",VLOOKUP(D15,Categorias!A:B,2,0)) | H15: =H14+F15-G15 -> 0
E16: =IF(ISERROR(VLOOKUP(D16,Categorias!A:B,2,0)),"",VLOOKUP(D16,Categorias!A:B,2,0)) | H16: =H15+F16-G16 -> 0
E17: =IF(ISERROR(VLOOKUP(D17,Categorias!A:B,2,0)),"",VLOOKUP(D17,Categorias!A:B,2,0)) | H17: =H16+F17-G17 -> 0
E18: =IF(ISERROR(VLOOKUP(D18,Categorias!A:B,2,0)),"",VLOOKUP(D18,Categorias!A:B,2,0)) | H18: =H17+F18-G18 -> 0
E19: =IF(ISERROR(VLOOKUP(D19,Categorias!A:B,2,0)),"",VLOOKUP(D19,Categorias!A:B,2,0)) | H19: =H18+F19-G19 -> 0
E20: =IF(ISERROR(VLOOKUP(D20,Categorias!A:B,2,0)),"",VLOOKUP(D20,Categorias!A:B,2,0)) | H20: =H19+F20-G20 -> 0
E21: =IF(ISERROR(VLOOKUP(D21,Categorias!A:B,2,0)),"",VLOOKUP(D21,Categorias!A:B,2,0)) | H21: =H20+F21-G21 -> 0
E22: =IF(ISERROR(VLOOKUP(D22,Categorias!A:B,2,0)),"",VLOOKUP(D22,Categorias!A:B,2,0)) | H22: =H21+F22-G22 -> 0
E23: =IF(ISERROR(VLOOKUP(D23,Categorias!A:B,2,0)),"",VLOOKUP(D23,Categorias!A:B,2,0)) | H23: =H22+F23-G23 -> 0
E24: =IF(ISERROR(VLOOKUP(D24,Categorias!A:B,2,0)),"",VLOOKUP(D24,Categorias!A:B,2,0)) | H24: =H23+F24-G24 -> 0
E25: =IF(ISERROR(VLOOKUP(D25,Categorias!A:B,2,0)),"",VLOOKUP(D25,Categorias!A:B,2,0)) | H25: =H24+F25-G25 -> 0
... E43: =IF(ISERROR(VLOOKUP(D43,Categorias!A:B,2,0)),"",VLOOKUP(D43,Categorias!A:B,2,0)) | H43: =H42+F43-G43 -> 0
H44: =H43+F44-G44 -> 0
E45: =IF(ISERROR(VLOOKUP(D45,Categorias!A:B,2,0)),"",VLOOKUP(D45,Categorias!A:B,2,0)) | H45: =H44+F45-G45 -> 0
E46: =IF(ISERROR(VLOOKUP(D46,Categorias!A:B,2,0)),"",VLOOKUP(D46,Categorias!A:B,2,0)) | H46: =H45+F46-G46 -> 0
E47: =IF(ISERROR(VLOOKUP(D47,Categorias!A:B,2,0)),"",VLOOKUP(D47,Categorias!A:B,2,0)) | H47: =H46+F47-G47 -> 0
E48: =IF(ISERROR(VLOOKUP(D48,Categorias!A:B,2,0)),"",VLOOKUP(D48,Categorias!A:B,2,0)) | H48: =H47+F48-G48 -> 0
E49: =IF(ISERROR(VLOOKUP(D49,Categorias!A:B,2,0)),"",VLOOKUP(D49,Categorias!A:B,2,0)) | H49: =H48+F49-G49 -> 0
E50: =IF(ISERROR(VLOOKUP(D50,Categorias!A:B,2,0)),"",VLOOKUP(D50,Categorias!A:B,2,0)) | H50: =H49+F50-G50 -> 0
E51: =IF(ISERROR(VLOOKUP(D51,Categorias!A:B,2,0)),"",VLOOKUP(D51,Categorias!A:B,2,0)) | H51: =H50+F51-G51 -> 0
E52: =IF(ISERROR(VLOOKUP(D52,Categorias!A:B,2,0)),"",VLOOKUP(D52,Categorias!A:B,2,0)) | H52: =H51+F52-G52 -> 0
E53: =IF(ISERROR(VLOOKUP(D53,Categorias!A:B,2,0)),"",VLOOKUP(D53,Categorias!A:B,2,0)) | H53: =H52+F53-G53 -> 0
E54: =IF(ISERROR(VLOOKUP(D54,Categorias!A:B,2,0)),"",VLOOKUP(D54,Categorias!A:B,2,0)) | H54: =H53+F54-G54 -> 0
E55: =IF(ISERROR(VLOOKUP(D55,Categorias!A:B,2,0)),"",VLOOKUP(D55,Categorias!A:B,2,0)) | H55: =H54+F55-G55 -> 0
E56: =IF(ISERROR(VLOOKUP(D56,Categorias!A:B,2,0)),"",VLOOKUP(D56,Categorias!A:B,2,0)) | H56: =H55+F56-G56 -> 0
... E254: =IF(ISERROR(VLOOKUP(D254,Categorias!A:B,2,0)),"",VLOOKUP(D254,Categorias!A:B,2,0)) | H254: =H253+F254-G254 -> 0

Sheet OUTUBRO
B2: CONTROLE DE CAIXA
B7: SALDOS INICIAL: | G7: =D8+D9+D10+G8+G9+G10 -> 0
B8: BANCO 1: | E8: BANCO 4:
B9: BANCO 2: | E9: BANCO 5:
B10: BANCO 3: | E10: DINHEIRO EM ESPÉCIE:
B12: Data | C12: Descrição | D12: Categoria | E12: Fluxo de Caixa | F12: Entrada | G12: Saída | H12: Saldo
E13: =IF(ISERROR(VLOOKUP(D13,Categorias!A:B,2,0)),"",VLOOKUP(D13,Categorias!A:B,2,0)) | H13: =G7+F13-G13 -> 0
E14: =IF(ISERROR(VLOOKUP(D14,Categorias!A:B,2,0)),"",VLOOKUP(D14,Categorias!A:B,2,0)) | H14: =H13+F14-G14 -> 0
E15: =IF(ISERROR(VLOOKUP(D15,Categorias!A:B,2,0)),"",VLOOKUP(D15,Categorias!A:B,2,0)) | H15: =H14+F15-G15 -> 0
E16: =IF(ISERROR(VLOOKUP(D16,Categorias!A:B,2,0)),"",VLOOKUP(D16,Categorias!A:B,2,0)) | H16: =H15+F16-G16 -> 0
E17: =IF(ISERROR(VLOOKUP(D17,Categorias!A:B,2,0)),"",VLOOKUP(D17,Categorias!A:B,2,0)) | H17: =H16+F17-G17 -> 0
E18: =IF(ISERROR(VLOOKUP(D18,Categorias!A:B,2,0)),"",VLOOKUP(D18,Categorias!A:B,2,0)) | H18: =H17+F18-G18 -> 0
E19: =IF(ISERROR(VLOOKUP(D19,Categorias!A:B,2,0)),"",VLOOKUP(D19,Categorias!A:B,2,0)) | H19: =H18+F19-G19 -> 0
E20: =IF(ISERROR(VLOOKUP(D20,Categorias!A:B,2,0)),"",VLOOKUP(D20,Categorias!A:B,2,0)) | H20: =H19+F20-G20 -> 0
E21: =IF(ISERROR(VLOOKUP(D21,Categorias!A:B,2,0)),"",VLOOKUP(D21,Categorias!A:B,2,0)) | H21: =H20+F21-G21 -> 0
E22: =IF(ISERROR(VLOOKUP(D22,Categorias!A:B,2,0)),"",VLOOKUP(D22,Categorias!A:B,2,0)) | H22: =H21+F22-G22 -> 0
E23: =IF(ISERROR(VLOOKUP(D23,Categorias!A:B,2,0)),"",VLOOKUP(D23,Categorias!A:B,2,0)) | H23: =H22+F23-G23 -> 0
E24: =IF(ISERROR(VLOOKUP(D24,Categorias!A:B,2,0)),"",VLOOKUP(D24,Categorias!A:B,2,0)) | H24: =H23+F24-G24 -> 0
E25: =IF(ISERROR(VLOOKUP(D25,Categorias!A:B,2,0)),"",VLOOKUP(D25,Categorias!A:B,2,0)) | H25: =H24+F25-G25 -> 0
... E43: =IF(ISERROR(VLOOKUP(D43,Categorias!A:B,2,0)),"",VLOOKUP(D43,Categorias!A:B,2,0)) | H43: =H42+F43-G43 -> 0
H44: =H43+F44-G44 -> 0
E45: =IF(ISERROR(VLOOKUP(D45,Categorias!A:B,2,0)),"",VLOOKUP(D45,Categorias!A:B,2,0)) | H45: =H44+F45-G45 -> 0
E46: =IF(ISERROR(VLOOKUP(D46,Categorias!A:B,2,0)),"",VLOOKUP(D46,Categorias!A:B,2,0)) | H46: =H45+F46-G46 -> 0
E47: =IF(ISERROR(VLOOKUP(D47,Categorias!A:B,2,0)),"",VLOOKUP(D47,Categorias!A:B,2,0)) | H47: =H46+F47-G47 -> 0
E48: =IF(ISERROR(VLOOKUP(D48,Categorias!A:B,2,0)),"",VLOOKUP(D48,Categorias!A:B,2,0)) | H48: =H47+F48-G48 -> 0
E49: =IF(ISERROR(VLOOKUP(D49,Categorias!A:B,2,0)),"",VLOOKUP(D49,Categorias!A:B,2,0)) | H49: =H48+F49-G49 -> 0
E50: =IF(ISERROR(VLOOKUP(D50,Categorias!A:B,2,0)),"",VLOOKUP(D50,Categorias!A:B,2,0)) | H50: =H49+F50-G50 -> 0
E51: =IF(ISERROR(VLOOKUP(D51,Categorias!A:B,2,0)),"",VLOOKUP(D51,Categorias!A:B,2,0)) | H51: =H50+F51-G51 -> 0
E52: =IF(ISERROR(VLOOKUP(D52,Categorias!A:B,2,0)),"",VLOOKUP(D52,Categorias!A:B,2,0)) | H52: =H51+F52-G52 -> 0
E53: =IF(ISERROR(VLOOKUP(D53,Categorias!A:B,2,0)),"",VLOOKUP(D53,Categorias!A:B,2,0)) | H53: =H52+F53-G53 -> 0
E54: =IF(ISERROR(VLOOKUP(D54,Categorias!A:B,2,0)),"",VLOOKUP(D54,Categorias!A:B,2,0)) | H54: =H53+F54-G54 -> 0
E55: =IF(ISERROR(VLOOKUP(D55,Categorias!A:B,2,0)),"",VLOOKUP(D55,Categorias!A:B,2,0)) | H55: =H54+F55-G55 -> 0
E56: =IF(ISERROR(VLOOKUP(D56,Categorias!A:B,2,0)),"",VLOOKUP(D56,Categorias!A:B,2,0)) | H56: =H55+F56-G56 -> 0
... E254: =IF(ISERROR(VLOOKUP(D254,Categorias!A:B,2,0)),"",VLOOKUP(D254,Categorias!A:B,2,0)) | H254: =H253+F254-G254 -> 0

Sheet NOVEMBRO
B2: CONTROLE DE CAIXA
B7: SALDOS INICIAL: | G7: =D8+D9+D10+G8+G9+G10 -> 0
B8: BANCO 1: | E8: BANCO 4:
B9: BANCO 2: | E9: BANCO 5:
B10: BANCO 3: | E10: DINHEIRO EM ESPÉCIE:
B12: Data | C12: Descrição | D12: Categoria | E12: Fluxo de Caixa | F12: Entrada | G12: Saída | H12: Saldo
